Workbook

Sheet 1
B2: CUENTAS POR COBRAR
B3: GESTION 2023 - 2024
C5: CLIENTE: | D5: Fabricio Tapia Castedo
C6: CELULAR: | D6: 67598385
C7: DESTINO: | D7: Cochabamba
C8: LINEA DE CREDITO: | D8: 120000
B10: NOTA DE VENTA | C10: NOTA DE ENTREGA | D10: FECHA DE DESPACHO | E10: MONTO P/COBRAR | F10: DEPÓSITO en Bs | G10: FECHA DE DEPÓSITO | H10: SALDO | I10: DIAS DE MORA | J10: OBSERVACION
B11: 220910 | D11: 44827 | E11: 763.8 | H11: =+E11-F11 -> 763.8
B12: 221011 | D12: 44859 | E12: 1087.43 | H12: =+H11+E12-F12 -> 1851.23
B13: 221102 | D13: 44872 | E13: 4715.4 | H13: =+H12+E13-F13 -> 6566.63
B14: 221106 | D14: 44880 | E14: 41504.2 | H14: =+H13+E14-F14 -> 48070.83
B15: 221123 | D15: 44895 | E15: 41223 | H15: =+H14+E15-F15 -> 89293.83
H16: =+H15+E16-F16 -> 89293.83
H17: =+H16+E17-F17 -> 89293.83
H18: =+H17+E18-F18 -> 89293.83
H19: =+H18+E19-F19 -> 89293.83
H20: =+H19+E20-F20 -> 89293.83
H21: =+H20+E21-F21 -> 89293.83
H22: =+H21+E22-F22 -> 89293.83
H23: =+H22+E23-F23 -> 89293.83
B24: TOTALES | E24: =SUM(E11:E23) -> 89293.83 | F24: =SUM(F11:F23) -> 0
F25: =+E24-F24 -> 89293.83
B28: Conductores de despachos a FABRICIO TAPIA
C29: JULIAN FLORES GONZALES | E29: Cel: | F29: 72898045
C30: JULIAN MARCANI CHUMACERO | E30: Cel:
C31: EDWIN BARRON DURAN | E31: Cel: | F31: 67620372
C32: FRANCISCO DIAS MAMANI | E32: Cel:
C33: FRANCISCO DIAS MAMANI | E33: Cel: | F33: 68623440
C35: Ya estan firmadas.

Sheet 2
B2: CUENTAS POR COBRAR
B3: GESTION 2023 - 2024
C5: CLIENTE: | D5: Edwin Fernandez Chirinos
C6: CELULAR: | D6: 70152337
C7: DESTINO: | D7: El Alto
C8: LINEA DE CREDITO:
B10: NOTA DE VENTA | C10: NOTA DE ENTREGA | D10: FECHA DE DESPACHO | E10: MONTO P/COBRAR | F10: DEPÓSITO en Bs | G10: FECHA DE DEPÓSITO | H10: SALDO | I10: DIAS DE MORA | J10: OBSERVACION
B11: 210731 | D11: 44406 | E11: 7798 | H11: =+E11-F11 -> 7798 | J11: En Proceso
B12: 210814 | D12: 44422 | E12: 39668.5 | H12: =+H11+E12-F12 -> 47466.5 | J12: En Proceso
B13: 210830 | D13: 44439 | E13: 41763.5 | H13: =+H12+E13-F13 -> 89230 | J13: En Proceso
H14: =+H13+E14-F14 -> 89230
H15: =+H14+E15-F15 -> 89230
H16: =+H15+E16-F16 -> 89230
H17: =+H16+E17-F17 -> 89230
H18: =+H17+E18-F18 -> 89230
H19: =+H18+E19-F19 -> 89230
H20: =+H19+E20-F20 -> 89230
H21: =+H20+E21-F21 -> 89230
B22: TOTALES | E22: =SUM(E11:E21) -> 89230 | F22: =SUM(F11:F21) -> 0

Sheet RECAU. JULIO 2025
A3: CUENTAS POR COBRAR A CLIENTES
A4: GESTION 2023 - 2024
A5: JUNIO - 2025
A6: Nº | B6: DISTRIBUIDOR | C6: DEPARTAMENTO | AI6: TOTAL MES
D7: 1 | E7: 2 | F7: 3 | G7: 4 | H7: Semana 1 | I7: 6 | J7: 7 | K7: 8 | L7: 9 | M7: 10 | N7: 11 | O7: Semana 2 | P7: 13 | Q7: 14 | R7: 15 | S7: 16 | T7: 17 | U7: 18 | V7: Semana 3 | W7: 20 | X7: 21 | Y7: 22 | Z7: 23 | AA7: 24 | AB7: 25 | AC7: Semana 4 | AD7: 27 | AE7: 28 | AF7: 29 | AG7: 28 | AH7: Semana 4
A8: 1 | B8: Fabricio Tapia Castedo | C8: Cochabamba | H8: =SUM(D8:G8) -> 0 | O8: =SUM(I8:N8) -> 0 | V8: =SUM(P8:U8) -> 0 | AC8: =SUM(W8:AB8) -> 0 | AH8: =SUM(AD8:AG8) -> 0 | AI8: =+H8+O8+V8+AH8 -> 0
A9: =1+A8 -> 2 | B9: Edwin Fernandez Chirinos | C9: El Alto | H9: =SUM(D9:G9) -> 0 | O9: =SUM(I9:N9) -> 0 | V9: =SUM(P9:U9) -> 0 | AC9: =SUM(W9:AB9) -> 0 | AH9: =SUM(AD9:AG9) -> 0 | AI9: =+H9+O9+V9+AH9 -> 0
A10: =1+A9 -> 3 | B10: Javier Caceres | C10: Cochabamba | H10: =SUM(D10:G10) -> 0 | O10: =SUM(I10:N10) -> 0 | V10: =SUM(P10:U10) -> 0 | AC10: =SUM(W10:AB10) -> 0 | AH10: =SUM(AD10:AG10) -> 0 | AI10: =+H10+O10+V10+AH10 -> 0
A11: =1+A10 -> 4 | B11: Juan Carlos Torrez Ayarde | C11: Tarija | H11: =SUM(D11:G11) -> 0 | O11: =SUM(I11:N11) -> 0 | V11: =SUM(P11:U11) -> 0 | AC11: =SUM(W11:AB11) -> 0 | AH11: =SUM(AD11:AG11) -> 0 | AI11: =+H11+O11+V11+AH11 -> 0
A12: =1+A11 -> 5 | B12: Carol Alejandra Noya | C12: Tarija | H12: =SUM(D12:G12) -> 0 | O12: =SUM(I12:N12) -> 0 | V12: =SUM(P12:U12) -> 0 | AC12: =SUM(W12:AB12) -> 0 | AH12: =SUM(AD12:AG12) -> 0 | AI12: =+H12+O12+V12+AH12 -> 0
A13: =1+A12 -> 6 | B13: Luis Alberto Chipana Peña | C13: Cochabamba | H13: =SUM(D13:G13) -> 0 | O13: =SUM(I13:N13) -> 0 | V13: =SUM(P13:U13) -> 0 | AC13: =SUM(W13:AB13) -> 0 | AH13: =SUM(AD13:AG13) -> 0 | AI13: =+H13+O13+V13+AH13 -> 0
A14: =1+A13 -> 7 | B14: Franz Carlos Alanez Flores | C14: El Alto | H14: =SUM(D14:G14) -> 0 | O14: =SUM(I14:N14) -> 0 | V14: =SUM(P14:U14) -> 0 | AC14: =SUM(W14:AB14) -> 0 | AH14: =SUM(AD14:AG14) -> 0 | AI14: =+H14+O14+V14+AH14 -> 0
A15: =1+A14 -> 8 | B15: Andrés Miguel Paniagua | C15: Oruro | H15: =SUM(D15:G15) -> 0 | O15: =SUM(I15:N15) -> 0 | V15: =SUM(P15:U15) -> 0 | AC15: =SUM(W15:AB15) -> 0 | AH15: =SUM(AD15:AG15) -> 0 | AI15: =+H15+O15+V15+AH15 -> 0
A16: =1+A15 -> 9 | B16: Alex Rolando Fernandez H. | C16: Oruro | H16: =SUM(D16:G16) -> 0 | O16: =SUM(I16:N16) -> 0 | V16: =SUM(P16:U16) -> 0 | AC16: =SUM(W16:AB16) -> 0 | AH16: =SUM(AD16:AG16) -> 0 | AI16: =+H16+O16+V16+AH16 -> 0
A17: =1+A16 -> 10 | B17: Franklin Ever Viveros | C17: Potosí | H17: =SUM(D17:G17) -> 0 | O17: =SUM(I17:N17) -> 0 | V17: =SUM(P17:U17) -> 0 | AC17: =SUM(W17:AB17) -> 0 | AH17: =SUM(AD17:AG17) -> 0 | AI17: =+H17+O17+V17+AH17 -> 0
A18: =1+A17 -> 11 | B18: Teofilo Ibañez Soliz | C18: Tarija | H18: =SUM(D18:G18) -> 0 | O18: =SUM(I18:N18) -> 0 | V18: =SUM(P18:U18) -> 0 | AC18: =SUM(W18:AB18) -> 0 | AH18: =SUM(AD18:AG18) -> 0 | AI18: =+H18+O18+V18+AH18 -> 0
A19: =1+A18 -> 12 | B19: Elsa Romay Padilla | C19: Uyuni | H19: =SUM(D19:G19) -> 0 | O19: =SUM(I19:N19) -> 0 | V19: =SUM(P19:U19) -> 0 | AC19: =SUM(W19:AB19) -> 0 | AH19: =SUM(AD19:AG19) -> 0 | AI19: =+H19+O19+V19+AH19 -> 0
A20: =1+A19 -> 13 | B20: Jorge Luis Vedia Arancibia | C20: Chuquisaca - Prov | H20: =SUM(D20:G20) -> 0 | O20: =SUM(I20:N20) -> 0 | V20: =SUM(P20:U20) -> 0 | AC20: =SUM(W20:AB20) -> 0 | AH20: =SUM(AD20:AG20) -> 0 | AI20: =+H20+O20+V20+AH20 -> 0
A21: =1+A20 -> 14 | B21: Celina Cruz Mendez | C21: Chuquisaca - Prov | H21: =SUM(D21:G21) -> 0 | O21: =SUM(I21:N21) -> 0 | V21: =SUM(P21:U21) -> 0 | AC21: =SUM(W21:AB21) -> 0 | AH21: =SUM(AD21:AG21) -> 0 | AI21: =+H21+O21+V21+AH21 -> 0
A22: =1+A28 -> 20 | B22: Marlene Paicho | C22: Ruta Colquechaca | H22: =SUM(D22:G22) -> 0 | O22: =SUM(I22:N22) -> 0 | V22: =SUM(P22:U22) -> 0 | AC22: =SUM(W22:AB22) -> 0 | AH22: =SUM(AD22:AG22) -> 0 | AI22: =H22+O22+V22+AH22 -> 0
A23: TOTAL CLIENTES MOROSOS | G23: =SUM(G8:G22) -> 0 | H23: =SUM(D23:G23) -> 0 | I23: =SUM(I8:I22) -> 0 | J23: =SUM(J8:J22) -> 0 | K23: =SUM(K8:K22) -> 0 | L23: =SUM(L8:L22) -> 0 | M23: =SUM(M8:M22) -> 0 | N23: =SUM(N8:N22) -> 0 | O23: =SUM(I23:N23) -> 0 | P23: =SUM(P8:P22) -> 0 | Q23: =SUM(Q8:Q22) -> 0 | R23: =SUM(R8:R22) -> 0 | S23: =SUM(S8:S22) -> 0 | T23: =SUM(T8:T22) -> 0 | U23: =SUM(U8:U22) -> 0 | V23: =SUM(P23:U23) -> 0 | W23: =SUM(W8:W22) -> 0 | X23: =SUM(X8:X22) -> 0 | Y23: =SUM(Y8:Y22) -> 0 | Z23: =SUM(Z8:Z22) -> 0 | AA23: =SUM(AA8:AA22) -> 0 | AB23: =SUM(AB8:AB22) -> 0 | AC23: =SUM(W23:AB23) -> 0 | AD23: =SUM(AD8:AD22) -> 0 | AG23: =SUM(AG8:AG22) -> 0 | AH23: =SUM(AD23:AG23) -> 0 | AI23: =SUM(AI8:AI22) -> 0
A24: =1+A21 -> 15 | B24: EMAPA NACIONAL | C24: NACIONAL | H24: =SUM(D24:G24) -> 0 | O24: =SUM(I24:N24) -> 0 | V24: =SUM(P24:U24) -> 0 | AC24: =SUM(W24:AB24) -> 0 | AH24: =SUM(AD24:AG24) -> 0 | AI24: =H24+O24+V24+AC24+AH24 -> 0
A25: =1+A24 -> 16 | B25: Gustavo Tellez Ugarte | C25: Santa Cruz | H25: =SUM(D25:G25) -> 0 | O25: =SUM(I25:N25) -> 0 | V25: =SUM(P25:U25) -> 0 | AC25: =SUM(W25:AB25) -> 0 | AH25: =SUM(AD25:AG25) -> 0 | AI25: =H25+O25+V25+AC25+AH25 -> 0
A26: =1+A25 -> 17 | B26: Cristhian Murillo | C26: Sucre | H26: =SUM(D26:G26) -> 0 | O26: =SUM(I26:N26) -> 0 | V26: =SUM(P26:U26) -> 0 | AC26: =SUM(W26:AB26) -> 0 | AG26: =+'Cristhian Murillo'!F43 -> 341500 | AH26: =SUM(AD26:AG26) -> 341500 | AI26: =H26+O26+V26+AC26+AH26 -> 341500
A27: =1+A26 -> 18 | B27: Sebastian Miranda | C27: Oruro | H27: =SUM(D27:G27) -> 0 | O27: =SUM(I27:N27) -> 0 | V27: =SUM(P27:U27) -> 0 | AC27: =SUM(W27:AB27) -> 0 | AH27: =SUM(AD27:AG27) -> 0 | AI27: =H27+O27+V27+AC27+AH27 -> 0
A28: =1+A27 -> 19 | B28: Norha Choque Talavera | C28: Potosí | H28: =SUM(D28:G28) -> 0 | O28: =SUM(I28:N28) -> 0 | V28: =SUM(P28:U28) -> 0 | AC28: =SUM(W28:AB28) -> 0 | AH28: =SUM(AD28:AG28) -> 0 | AI28: =H28+O28+V28+AC28+AH28 -> 0
A29: =1+A28 -> 20 | B29: Orlando Aldunate M. | C29: Tarija | H29: =SUM(D29:G29) -> 0 | O29: =SUM(I29:N29) -> 0 | V29: =SUM(P29:U29) -> 0 | AC29: =SUM(W29:AB29) -> 0 | AG29: =+'Orlando Aldunate'!L23 -> 136757.5 | AH29: =SUM(AD29:AG29) -> 136757.5 | AI29: =H29+O29+V29+AC29+AH29 -> 136757.5
A30: =1+A29 -> 21 | B30: Fausto Condori | C30: Cochabamba | H30: =SUM(D30:G30) -> 0 | O30: =SUM(I30:N30) -> 0 | V30: =SUM(P30:U30) -> 0 | AC30: =SUM(W30:AB30) -> 0 | AH30: =SUM(AD30:AG30) -> 0 | AI30: =H30+O30+V30+AC30+AH30 -> 0
A31: =1+A30 -> 22 | B31: Flora Yapuchura | C31: La Paz | H31: =SUM(D31:G31) -> 0 | O31: =SUM(I31:N31) -> 0 | V31: =SUM(P31:U31) -> 0 | AC31: =SUM(W31:AB31) -> 0 | AH31: =SUM(AD31:AG31) -> 0 | AI31: =H31+O31+V31+AC31+AH31 -> 0
A32: =1+A31 -> 23 | B32: Willy Quispe | C32: El Alto | H32: =SUM(D32:G32) -> 0 | O32: =SUM(I32:N32) -> 0 | V32: =SUM(P32:U32) -> 0 | AC32: =SUM(W32:AB32) -> 0 | AH32: =SUM(AD32:AG32) -> 0 | AI32: =H32+O32+V32+AC32+AH32 -> 0
A33: =1+A32 -> 24 | B33: Andrez Lopez | C33: Potosí | H33: =SUM(D33:G33) -> 0 | O33: =SUM(I33:N33) -> 0 | V33: =SUM(P33:U33) -> 0 | AC33: =SUM(W33:AB33) -> 0 | AH33: =SUM(AD33:AG33) -> 0 | AI33: =H33+O33+V33+AC33+AH33 -> 0
A34: =1+A33 -> 25 | B34: Miguel Angel Mora | C34: Potosí | H34: =SUM(D34:G34) -> 0 | O34: =SUM(I34:N34) -> 0 | V34: =SUM(P34:U34) -> 0 | AC34: =SUM(W34:AB34) -> 0 | AH34: =SUM(AD34:AG34) -> 0 | AI34: =H34+O34+V34+AC34+AH34 -> 0
A35: =1+A34 -> 26 | B35: GAMS Desarrollo Productivo | C35: Sucre | H35: =SUM(D35:G35) -> 0 | O35: =SUM(I35:N35) -> 0 | V35: =SUM(P35:U35) -> 0 | AC35: =SUM(W35:AB35) -> 0 | AG35: =+GAMS!F12 -> 11745 | AH35: =SUM(AD35:AG35) -> 11745 | AI35: =H35+O35+V35+AC35+AH35 -> 11745
A36: =1+A35 -> 27 | B36: GAMS Direccion Administrativa | C36: Sucre | H36: =SUM(D36:G36) -> 0 | O36: =SUM(I36:N36) -> 0 | V36: =SUM(P36:U36) -> 0 | AC36: =SUM(W36:AB36) -> 0 | AH36: =SUM(AD36:AG36) -> 0 | AI36: =H36+O36+V36+AC36+AH36 -> 0
A37: =1+A36 -> 28 | B37: Carmen Cruz | C37: Potosí | H37: =SUM(D37:G37) -> 0 | O37: =SUM(I37:N37) -> 0 | V37: =SUM(P37:U37) -> 0 | AC37: =SUM(W37:AB37) -> 0 | AG37: =+#REF! -> #REF! | AH37: =SUM(AD37:AG37) -> #REF! | AI37: =H37+O37+V37+AC37+AH37 -> #REF!
A38: =1+A37 -> 29 | B38: Judith | C38: Cochabamba | H38: =SUM(D38:G38) -> 0 | O38: =SUM(I38:N38) -> 0 | V38: =SUM(P38:U38) -> 0 | AC38: =SUM(W38:AB38) -> 0 | AH38: =SUM(AD38:AG38) -> 0 | AI38: =H38+O38+V38+AC38+AH38 -> 0
A39: =1+A38 -> 30 | B39: Kevin | C39: Oruro | H39: =SUM(D39:G39) -> 0 | O39: =SUM(I39:N39) -> 0 | V39: =SUM(P39:U39) -> 0 | AC39: =SUM(W39:AB39) -> 0 | AH39: =SUM(AD39:AG39) -> 0 | AI39: =H39+O39+V39+AC39+AH39 -> 0
A40: =1+A39 -> 31 | B40: Jorge Saavedra | C40: Tupiza | H40: =SUM(D40:G40) -> 0 | O40: =SUM(I40:N40) -> 0 | V40: =SUM(P40:U40) -> 0 | AC40: =SUM(W40:AB40) -> 0 | AG40: =+#REF! -> #REF! | AH40: =SUM(AD40:AG40) -> #REF! | AI40: =H40+O40+V40+AC40+AH40 -> #REF!
A41: =1+A40 -> 32 | B41: Jenrry | C41: Chile | H41: =SUM(D41:G41) -> 0 | O41: =SUM(I41:N41) -> 0 | V41: =SUM(P41:U41) -> 0 | AC41: =SUM(W41:AB41) -> 0 | AG41: =+#REF! -> #REF! | AH41: =SUM(AD41:AG41) -> #REF! | AI41: =H41+O41+V41+AC41+AH41 -> #REF!
A42: =1+A41 -> 33 | B42: Eddy | C42: Chile | H42: =SUM(D42:G42) -> 0 | O42: =SUM(I42:N42) -> 0 | V42: =SUM(P42:U42) -> 0 | AC42: =SUM(W42:AB42) -> 0 | AG42: =+#REF! -> #REF! | AH42: =SUM(AD42:AG42) -> #REF! | AI42: =H42+O42+V42+AC42+AH42 -> #REF!
...

Sheet 3-Fausto C
B2: CUENTAS POR COBRAR
B3: GESTION 2023 - 2024
C5: CLIENTE: | D5: Javier Caceres Parada
C6: CELULAR: | D6: 74333570
C7: DESTINO: | D7: Cochabamba
C8: LINEA DE CREDITO: | D8: 80000
B10: NOTA DE VENTA | C10: NOTA DE ENTREGA | D10: FECHA DE DESPACHO | E10: MONTO P/COBRAR | F10: DEPÓSITO en Bs | G10: FECHA DE DEPÓSITO | H10: SALDO | I10: DIAS DE MORA | J10: OBSERVACION
B11: 230328 | C11: - | D11: 45010 | E11: 9977.9 | H11: =+E11-F11 -> 9977.9
B12: 230511 | C12: 294 | D12: 45054 | E12: 39134 | H12: =+H11+E12-F12 -> 49111.9
B13: 230644 | C13: 370 | D13: 45106 | E13: 33574 | H13: =+H12+E13-F13 -> 82685.9
H14: =+H13+E14-F14 -> 82685.9
H15: =+H14+E15-F15 -> 82685.9
H16: =+H15+E16-F16 -> 82685.9
H17: =+H16+E17-F17 -> 82685.9
H18: =+H17+E18-F18 -> 82685.9
B19: TOTALES | E19: =SUM(E11:E18) -> 82685.9 | F19: =SUM(F11:F18) -> 0
F20: =+E19-F19 -> 82685.9
C23: CLIENTE: | D23: Fausto Condori
C24: CELULAR:
C25: DESTINO: | D25: Cochabamba
C26: LINEA DE CREDITO:
B28: NOTA DE VENTA | C28: NOTA DE ENTREGA | D28: FECHA DE DESPACHO | E28: MONTO P/COBRAR | F28: DEPÓSITO en Bs | G28: FECHA DE DEPÓSITO | H28: SALDO | I28: DIAS DE MORA | J28: OBSERVACION
B29: 230903 | C29: 479 | D29: 45173 | E29: 33522 | F29: 20000 | G29: 45171 | H29: =+E29-F29 -> 13522
B30: 230923 | C30: 505 | D30: 45178 | E30: 62755 | F30: 13522 | G30: 45175 | H30: =+H29+E30-F30 -> 62755
B31: 230958 | C31: 538 | D31: 45194 | E31: 30904.8 | F31: 25000 | G31: 45178 | H31: =+H30+E31-F31 -> 68659.8
B32: 231058 | C32: 618 | D32: 45229 | E32: 71602.8 | F32: 37755 | G32: 45182 | H32: =+H31+E32-F32 -> 102507.6
F33: 14224.5 | G33: 45194 | H33: =+H32+E33-F33 -> 88283.1
F34: 16680.3 | G34: 45197 | H34: =+H33+E34-F34 -> 71602.8
F35: 50000 | G35: 45230 | H35: =+H34+E35-F35 -> 21602.8
F36: 21600.8 | G36: 45246 | H36: =+H35+E36-F36 -> 2
B37: 240243 | C37: 863 | D37: 45346 | E37: 26400 | F37: 26400 | G37: 45348 | H37: =+H36+E37-F37 -> 2
B38: 240437 | C38: 981 | D38: 45399 | E38: 36800 | F38: 36800 | G38: 45399 | H38: =+H37+E38-F38 -> 2
B39: 240736 | C39: 1180 | D39: 45492 | E39: 36420 | F39: 36420 | G39: 45492 | H39: =+H38+E39-F39 -> 2 | J39: Marco Antonio Condori Flores | L39: BU
B40: 240751 | C40: 1195 | D40: 45498 | E40: 41646 | F40: 37930 | G40: 45498 | H40: =+H39+E40-F40 -> 3718 | J40: FAUSTO | L40: BNB
F41: 3650 | G41: 45498 | H41: =+H40+E41-F41 -> 68 | J41: ELIANA CONDORI | L41: BNB | M41: =SUM(F39:F41) -> 78000
B42: 240839 | C42: 1243 | D42: 45532 | E42: 38219 | F42: 23300 | G42: 45532 | H42: =+H41+E42-F42 -> 14987
F43: 20000 | G43: 45532 | H43: =+H42+E43-F43 -> -5013 | M43: =SUM(F42:F43) -> 43300
B44: 240905 | C44: 1260 | D44: 45539 | E44: 53566 | F44: 30000 | G44: 45539 | H44: =+H43+E44-F44 -> 18553
F45: 10000 | G45: 45539 | H45: =+H44+E45-F45 -> 8553
F46: 8485 | G46: 45540 | H46: =+H45+E46-F46 -> 68 | M46: =SUM(F44:F46) -> 48485
...

Sheet 4
B2: CUENTAS POR COBRAR
B3: GESTION 2023 - 2024
C5: CLIENTE: | D5: Juan Carlos Torrez Ayarde
C6: CELULAR: | D6: 78250301
C7: DESTINO: | D7: Tarija
C8: LINEA DE CREDITO: | D8: 80000
B10: NOTA DE VENTA | C10: NOTA DE ENTREGA | D10: FECHA DE DESPACHO | E10: MONTO P/COBRAR | F10: DEPÓSITO en Bs | G10: FECHA DE DEPÓSITO | H10: SALDO | I10: DIAS DE MORA | J10: OBSERVACION
B11: 220915 | D11: 44833 | E11: 22998.2 | H11: =+E11-F11 -> 22998.2
B12: 221005 | D12: 44851 | E12: 39971 | H12: =+H11+E12-F12 -> 62969.2
F13: 5000 | G13: 45603 | H13: =+H12+E13-F13 -> 57969.2 | I13: BNB | J13: CUIZA CAIGUARA ESPERANZA
F14: 5000 | G14: 45603 | H14: =+H13+E14-F14 -> 52969.2 | I14: BNB | J14: CUIZA CAIGUARA ESPERANZA
F15: 5000 | G15: 45608 | H15: =+H14+E15-F15 -> 47969.2 | I15: BNB | J15: CUIZA CAIGUARA ESPERANZA
F16: 10000 | G16: 45608 | H16: =+H15+E16-F16 -> 37969.2 | I16: BNB | J16: CUIZA CAIGUARA ESPERANZA
F17: 10000 | G17: 45609 | H17: =+H16+E17-F17 -> 27969.2 | I17: BNB | J17: CUIZA CAIGUARA ESPERANZA
F18: 15000 | G18: 45611 | H18: =+H17+E18-F18 -> 12969.2 | I18: BNB | J18: CUIZA CAIGUARA ESPERANZA
F19: 12969.2 | G19: - | H19: =+H18+E19-F19 -> 0 | J19: se perdono por cancelar bs50.000.-
H20: =+H19+E20-F20 -> 0
H21: =+H20+E21-F21 -> 0
H22: =+H21+E22-F22 -> 0
H23: =+H22+E23-F23 -> 0
B24: TOTALES | E24: =SUM(E11:E23) -> 62969.2 | F24: =SUM(F11:F23) -> 62969.2
F25: =+E24-F24 -> 0

Sheet 5
B2: CUENTAS POR COBRAR
B3: GESTION 2023 - 2024
C5: CLIENTE: | D5: Carol Alejandra Noya
C6: CELULAR:
C7: DESTINO: | D7: Tarija
C8: LINEA DE CREDITO: | D8: 80000
B10: NOTA DE VENTA | C10: NOTA DE ENTREGA | D10: FECHA DE DESPACHO | E10: MONTO P/COBRAR | F10: DEPÓSITO en Bs | G10: FECHA DE DEPÓSITO | H10: SALDO | I10: DIAS DE MORA | J10: OBSERVACION
B11: 210105 | D11: 44940 | E11: 41100.6 | H11: =+E11-F11 -> 41100.6
H12: =+H11+E12-F12 -> 41100.6
H13: =+H12+E13-F13 -> 41100.6
H14: =+H13+E14-F14 -> 41100.6
H15: =+H14+E15-F15 -> 41100.6
H16: =+H15+E16-F16 -> 41100.6
H17: =+H16+E17-F17 -> 41100.6
H18: =+H17+E18-F18 -> 41100.6
H19: =+H18+E19-F19 -> 41100.6
H20: =+H19+E20-F20 -> 41100.6
H21: =+H20+E21-F21 -> 41100.6
H22: =+H21+E22-F22 -> 41100.6
H23: =+H22+E23-F23 -> 41100.6
B24: TOTALES | E24: =SUM(E11:E23) -> 41100.6 | F24: =SUM(F11:F23) -> 0
F25: =+E24-F24 -> 41100.6

Sheet 6
B2: CUENTAS POR COBRAR
B3: GESTION 2023 - 2024
C5: CLIENTE: | D5: Luis Alberto Chipana Peña
C6: CELULAR: | D6: 79347671
C7: DESTINO: | D7: Cochabamba
C8: LINEA DE CREDITO:
B10: NOTA DE VENTA | C10: NOTA DE ENTREGA | D10: FECHA DE DESPACHO | E10: MONTO P/COBRAR | F10: DEPÓSITO en Bs | G10: FECHA DE DEPÓSITO | H10: SALDO | I10: DIAS DE MORA | J10: OBSERVACION
B11: 210902 | D11: 44440 | E11: 35550 | H11: =+E11-F11 -> 35550 | J11: Se comprometio a pagar cada mes Bs. 1000
H12: =+H11+E12-F12 -> 35550
H13: =+H12+E13-F13 -> 35550
H14: =+H13+E14-F14 -> 35550
H15: =+H14+E15-F15 -> 35550
H16: =+H15+E16-F16 -> 35550
H17: =+H16+E17-F17 -> 35550
H18: =+H17+E18-F18 -> 35550
H19: =+H18+E19-F19 -> 35550
H20: =+H19+E20-F20 -> 35550
H21: =+H20+E21-F21 -> 35550
B22: TOTALES | E22: =SUM(E11:E21) -> 35550 | F22: =SUM(F11:F21) -> 0

Sheet 7
B2: CUENTAS POR COBRAR
B3: GESTION 2023 - 2024
C5: CLIENTE: | D5: Franz Carlos Alanez Flores
C6: CELULAR:
C7: DESTINO: | D7: El Alto
C8: LINEA DE CREDITO:
B10: NOTA DE VENTA | C10: NOTA DE ENTREGA | D10: FECHA DE DESPACHO | E10: MONTO P/COBRAR | F10: DEPÓSITO en Bs | G10: FECHA DE DEPÓSITO | H10: SALDO | I10: DIAS DE MORA | J10: OBSERVACION
B11: 210118 | D11: 44953 | E11: 33500 | H11: =+E11-F11 -> 33500 | J11: En Proceso
H12: =+H11+E12-F12 -> 33500
H13: =+H12+E13-F13 -> 33500
H14: =+H13+E14-F14 -> 33500
H15: =+H14+E15-F15 -> 33500
H16: =+H15+E16-F16 -> 33500
H17: =+H16+E17-F17 -> 33500
H18: =+H17+E18-F18 -> 33500
H19: =+H18+E19-F19 -> 33500
H20: =+H19+E20-F20 -> 33500
H21: =+H20+E21-F21 -> 33500
E22: =SUM(E11:E21) -> 33500 | F22: =SUM(F11:F21) -> 0

Sheet 8
B2: CUENTAS POR COBRAR
B3: GESTION 2023 - 2024
C5: CLIENTE: | D5: Alvaro Choque Blanco
C6: CELULAR: | D6: 63568941
C7: DESTINO: | D7: ORURO
C8: LINEA DE CREDITO: | D8: 40000
B10: NOTA DE VENTA | C10: NOTA DE ENTREGA | D10: FECHA DE DESPACHO | E10: MONTO P/COBRAR | F10: DEPÓSITO en Bs | G10: FECHA DE DEPÓSITO | H10: SALDO | I10: DIAS DE MORA | J10: OBSERVACION
B11: 230205 | D11: 44966 | E11: 32664.2 | F11: 2800 | G11: 45142 | H11: =+E11-F11 -> 29864.2
F12: 10000 | G12: 45166 | H12: =+H11+E12-F12 -> 19864.2
F13: 19864.2 | G13: 45224 | H13: =+H12+E13-F13 -> 0
H14: =+H13+E14-F14 -> 0
H15: =+H14+E15-F15 -> 0
H16: =+H15+E16-F16 -> 0
H17: =+H16+E17-F17 -> 0
H18: =+H17+E18-F18 -> 0
H19: =+H18+E19-F19 -> 0
B20: TOTALES | E20: =SUM(E11:E19) -> 32664.2 | F20: =SUM(F11:F19) -> 32664.2
F21: =+E20-F20 -> 0

Sheet 9
B2: CUENTAS POR COBRAR
B3: GESTION 2023 - 2024
C5: CLIENTE: | D5: Andrés Miguel Paniagua
C6: CELULAR: | D6: 77145507
C7: DESTINO: | D7: ORURO
C8: LINEA DE CREDITO: | D8: 60000
B10: NOTA DE VENTA | C10: NOTA DE ENTREGA | D10: FECHA DE DESPACHO | E10: MONTO P/COBRAR | F10: DEPÓSITO en Bs | G10: FECHA DE DEPÓSITO | H10: SALDO | I10: DIAS DE MORA | J10: OBSERVACION
B11: 220916 | D11: 44834 | E11: 24351.9 | H11: =+E11-F11 -> 24351.9
H12: =+H11+E12-F12 -> 24351.9
H13: =+H12+E13-F13 -> 24351.9
H14: =+H13+E14-F14 -> 24351.9
H15: =+H14+E15-F15 -> 24351.9
H16: =+H15+E16-F16 -> 24351.9
H17: =+H16+E17-F17 -> 24351.9
H18: =+H17+E18-F18 -> 24351.9
H19: =+H18+E19-F19 -> 24351.9
B20: TOTALES | E20: =SUM(E11:E19) -> 24351.9 | F20: =SUM(F11:F19) -> 0
F21: =+E20-F20 -> 24351.9

Sheet 10
B2: CUENTAS POR COBRAR
B3: GESTION 2023 - 2024
C5: CLIENTE: | D5: Alex Rolando Fernandez H.
C6: CELULAR: | D6: 68320858
C7: DESTINO: | D7: Oruro
C8: LINEA DE CREDITO:
B10: NOTA DE VENTA | C10: NOTA DE ENTREGA | D10: FECHA DE DESPACHO | E10: MONTO P/COBRAR | F10: DEPÓSITO en Bs | G10: FECHA DE DEPÓSITO | H10: SALDO | I10: DIAS DE MORA | J10: OBSERVACION
B11: 211215 | D11: 44545 | E11: 23293 | H11: =+E11-F11 -> 23293 | J11: Se comprometio a pagar cada mes Bs. 5000
H12: =+H11+E12-F12 -> 23293
H13: =+H12+E13-F13 -> 23293
H14: =+H13+E14-F14 -> 23293
H15: =+H14+E15-F15 -> 23293
H16: =+H15+E16-F16 -> 23293
H17: =+H16+E17-F17 -> 23293
H18: =+H17+E18-F18 -> 23293
H19: =+H18+E19-F19 -> 23293
H20: =+H19+E20-F20 -> 23293
H21: =+H20+E21-F21 -> 23293
B22: TOTALES | E22: =SUM(E11:E21) -> 23293 | F22: =SUM(F11:F21) -> 0

Sheet 11
B2: CUENTAS POR COBRAR
B3: GESTION 2023 - 2024
C5: CLIENTE: | D5: Franklin Ever Viveros
C6: CELULAR: | D6: 68374333
C7: DESTINO: | D7: POTOSI
C8: LINEA DE CREDITO: | D8: 60000
B10: NOTA DE VENTA | C10: NOTA DE ENTREGA | D10: FECHA DE DESPACHO | E10: MONTO P/COBRAR | F10: DEPÓSITO en Bs | G10: FECHA DE DEPÓSITO | H10: SALDO | I10: DIAS DE MORA | J10: OBSERVACION
B11: 220913 | D11: 44832 | E11: 11132.55 | F11: 0 | G11: - | H11: =+E11-F11 -> 11132.55
H12: =+H11+E12-F12 -> 11132.55
H13: =+H12+E13-F13 -> 11132.55
H14: =+H13+E14-F14 -> 11132.55
H15: =+H14+E15-F15 -> 11132.55
H16: =+H15+E16-F16 -> 11132.55
H17: =+H16+E17-F17 -> 11132.55
H18: =+H17+E18-F18 -> 11132.55
H19: =+H18+E19-F19 -> 11132.55
H20: =+H19+E20-F20 -> 11132.55
H21: =+H20+E21-F21 -> 11132.55
H22: =+H21+E22-F22 -> 11132.55
H23: =+H22+E23-F23 -> 11132.55
B24: TOTALES | E24: =SUM(E11:E23) -> 11132.55 | F24: =SUM(F11:F23) -> 0
F25: =+E24-F24 -> 11132.55

Sheet 12
B2: CUENTAS POR COBRAR
B3: GESTION 2023 - 2024
C5: CLIENTE: | D5: Teofilo Ibañez Soliz
C6: CELULAR: | D6: 71861156
C7: DESTINO: | D7: Tarija
C8: LINEA DE CREDITO:
B10: NOTA DE VENTA | C10: NOTA DE ENTREGA | D10: FECHA DE DESPACHO | E10: MONTO P/COBRAR | F10: DEPÓSITO en Bs | G10: FECHA DE DEPÓSITO | H10: SALDO | I10: DIAS DE MORA | J10: OBSERVACION
B11: 210518 | D11: 44334 | E11: 7220.5 | H11: =+E11-F11 -> 7220.5 | J11: En Proceso
H12: =+H11+E12-F12 -> 7220.5
H13: =+H12+E13-F13 -> 7220.5
H14: =+H13+E14-F14 -> 7220.5
H15: =+H14+E15-F15 -> 7220.5
H16: =+H15+E16-F16 -> 7220.5
H17: =+H16+E17-F17 -> 7220.5
H18: =+H17+E18-F18 -> 7220.5
H19: =+H18+E19-F19 -> 7220.5
H20: =+H19+E20-F20 -> 7220.5
H21: =+H20+E21-F21 -> 7220.5
E22: =SUM(E11:E21) -> 7220.5 | F22: =SUM(F11:F21) -> 0

Sheet 13
B2: CUENTAS POR COBRAR
B3: GESTION 2023 - 2024
C5: CLIENTE: | D5: Elsa Romay Padilla
C6: CELULAR: | D6: 74282999
C7: DESTINO: | D7: UYUNI
C8: LINEA DE CREDITO: | D8: 30000
B10: NOTA DE VENTA | C10: NOTA DE ENTREGA | D10: FECHA DE DESPACHO | E10: MONTO P/COBRAR | F10: DEPÓSITO en Bs | G10: FECHA DE DEPÓSITO | H10: SALDO | I10: DIAS DE MORA | J10: OBSERVACION
B11: 220507 | D11: 44688 | E11: 6470 | F11: 0 | G11: - | H11: =+E11-F11 -> 6470
B12: 250112 | C12: 1538 | D12: 45666 | E12: 30305 | F12: 36775 | G12: 45654 | H12: =+H11+E12-F12 -> 0 | J12: Elsa Romay Padilla | K12: BU
H13: =+H12+E13-F13 -> 0
H14: =+H13+E14-F14 -> 0
H15: =+H14+E15-F15 -> 0
H16: =+H15+E16-F16 -> 0
H17: =+H16+E17-F17 -> 0
H18: =+H17+E18-F18 -> 0
B19: TOTALES | E19: =SUM(E11:E18) -> 36775 | F19: =SUM(F11:F18) -> 36775
F20: =+E19-F19 -> 0

Sheet 14
B2: CUENTAS POR COBRAR
B3: GESTION 2023 - 2024
C5: CLIENTE: | D5: Jorge Luis Vedia Arancibia
C6: CELULAR: | D6: 73476601
C7: DESTINO: | D7: Chuquisaca - Provincias
C8: LINEA DE CREDITO:
B10: NOTA DE VENTA | C10: NOTA DE ENTREGA | D10: FECHA DE DESPACHO | E10: MONTO P/COBRAR | F10: DEPÓSITO en Bs | G10: FECHA DE DEPÓSITO | H10: SALDO | I10: DIAS DE MORA | J10: OBSERVACION
B11: 210630 | D11: 44376 | E11: 3974.5 | H11: =+E11-F11 -> 3974.5 | J11: En Proceso
H12: =+H11+E12-F12 -> 3974.5
H13: =+H12+E13-F13 -> 3974.5
H14: =+H13+E14-F14 -> 3974.5
H15: =+H14+E15-F15 -> 3974.5
H16: =+H15+E16-F16 -> 3974.5
H17: =+H16+E17-F17 -> 3974.5
H18: =+H17+E18-F18 -> 3974.5
H19: =+H18+E19-F19 -> 3974.5
H20: =+H19+E20-F20 -> 3974.5
H21: =+H20+E21-F21 -> 3974.5
E22: =SUM(E11:E21) -> 3974.5 | F22: =SUM(F11:F21) -> 0

Sheet 15
B2: CUENTAS POR COBRAR
B3: GESTION 2023 - 2024
C5: CLIENTE: | D5: Celina Cruz Mendez
C6: CELULAR:
C7: DESTINO: | D7: Chuquisaca - Provincias
C8: LINEA DE CREDITO:
B10: NOTA DE VENTA | C10: NOTA DE ENTREGA | D10: FECHA DE DESPACHO | E10: MONTO P/COBRAR | F10: DEPÓSITO en Bs | G10: FECHA DE DEPÓSITO | H10: SALDO | I10: DIAS DE MORA | J10: OBSERVACION
B11: 210504 | D11: 44323 | E11: 3220 | H11: =+E11-F11 -> 3220 | J11: En Proceso
H12: =+H11+E12-F12 -> 3220
H13: =+H12+E13-F13 -> 3220
H14: =+H13+E14-F14 -> 3220
H15: =+H14+E15-F15 -> 3220
H16: =+H15+E16-F16 -> 3220
H17: =+H16+E17-F17 -> 3220
H18: =+H17+E18-F18 -> 3220
H19: =+H18+E19-F19 -> 3220
H20: =+H19+E20-F20 -> 3220
H21: =+H20+E21-F21 -> 3220
E22: =SUM(E11:E21) -> 3220 | F22: =SUM(F11:F21) -> 0

Sheet RECAU. ABRIL 2025
A3: CUENTAS POR COBRAR A CLIENTES
A4: GESTION 2023 - 2024
A5: MARZO - 2025
A6: Nº | B6: DISTRIBUIDOR | C6: DEPARTAMENTO | AI6: TOTAL MES
D7: 1 | E7: 2 | F7: 3 | G7: 4 | H7: Semana 1 | I7: 6 | J7: 7 | K7: 8 | L7: 9 | M7: 10 | N7: 11 | O7: Semana 2 | P7: 13 | Q7: 14 | R7: 15 | S7: 16 | T7: 17 | U7: 18 | V7: Semana 3 | W7: 20 | X7: 21 | Y7: 22 | Z7: 23 | AA7: 24 | AB7: 25 | AC7: Semana 4 | AD7: 27 | AE7: 28 | AF7: 29 | AG7: 28 | AH7: Semana 4
A8: 1 | B8: Fabricio Tapia Castedo | C8: Cochabamba | H8: =SUM(D8:G8) -> 0 | O8: =SUM(I8:N8) -> 0 | V8: =SUM(P8:U8) -> 0 | AC8: =SUM(W8:AB8) -> 0 | AH8: =SUM(AD8:AG8) -> 0 | AI8: =+H8+O8+V8+AH8 -> 0
A9: =1+A8 -> 2 | B9: Edwin Fernandez Chirinos | C9: El Alto | H9: =SUM(D9:G9) -> 0 | O9: =SUM(I9:N9) -> 0 | V9: =SUM(P9:U9) -> 0 | AC9: =SUM(W9:AB9) -> 0 | AH9: =SUM(AD9:AG9) -> 0 | AI9: =+H9+O9+V9+AH9 -> 0
A10: =1+A9 -> 3 | B10: Javier Caceres | C10: Cochabamba | H10: =SUM(D10:G10) -> 0 | O10: =SUM(I10:N10) -> 0 | V10: =SUM(P10:U10) -> 0 | AC10: =SUM(W10:AB10) -> 0 | AH10: =SUM(AD10:AG10) -> 0 | AI10: =+H10+O10+V10+AH10 -> 0
A11: =1+A10 -> 4 | B11: Juan Carlos Torrez Ayarde | C11: Tarija | H11: =SUM(D11:G11) -> 0 | O11: =SUM(I11:N11) -> 0 | V11: =SUM(P11:U11) -> 0 | AC11: =SUM(W11:AB11) -> 0 | AH11: =SUM(AD11:AG11) -> 0 | AI11: =+H11+O11+V11+AH11 -> 0
A12: =1+A11 -> 5 | B12: Carol Alejandra Noya | C12: Tarija | H12: =SUM(D12:G12) -> 0 | O12: =SUM(I12:N12) -> 0 | V12: =SUM(P12:U12) -> 0 | AC12: =SUM(W12:AB12) -> 0 | AH12: =SUM(AD12:AG12) -> 0 | AI12: =+H12+O12+V12+AH12 -> 0
A13: =1+A12 -> 6 | B13: Luis Alberto Chipana Peña | C13: Cochabamba | H13: =SUM(D13:G13) -> 0 | O13: =SUM(I13:N13) -> 0 | V13: =SUM(P13:U13) -> 0 | AC13: =SUM(W13:AB13) -> 0 | AH13: =SUM(AD13:AG13) -> 0 | AI13: =+H13+O13+V13+AH13 -> 0
A14: =1+A13 -> 7 | B14: Franz Carlos Alanez Flores | C14: El Alto | H14: =SUM(D14:G14) -> 0 | O14: =SUM(I14:N14) -> 0 | V14: =SUM(P14:U14) -> 0 | AC14: =SUM(W14:AB14) -> 0 | AH14: =SUM(AD14:AG14) -> 0 | AI14: =+H14+O14+V14+AH14 -> 0
A15: =1+A14 -> 8 | B15: Andrés Miguel Paniagua | C15: Oruro | H15: =SUM(D15:G15) -> 0 | O15: =SUM(I15:N15) -> 0 | V15: =SUM(P15:U15) -> 0 | AC15: =SUM(W15:AB15) -> 0 | AH15: =SUM(AD15:AG15) -> 0 | AI15: =+H15+O15+V15+AH15 -> 0
A16: =1+A15 -> 9 | B16: Alex Rolando Fernandez H. | C16: Oruro | H16: =SUM(D16:G16) -> 0 | O16: =SUM(I16:N16) -> 0 | V16: =SUM(P16:U16) -> 0 | AC16: =SUM(W16:AB16) -> 0 | AH16: =SUM(AD16:AG16) -> 0 | AI16: =+H16+O16+V16+AH16 -> 0
A17: =1+A16 -> 10 | B17: Franklin Ever Viveros | C17: Potosí | H17: =SUM(D17:G17) -> 0 | O17: =SUM(I17:N17) -> 0 | V17: =SUM(P17:U17) -> 0 | AC17: =SUM(W17:AB17) -> 0 | AH17: =SUM(AD17:AG17) -> 0 | AI17: =+H17+O17+V17+AH17 -> 0
A18: =1+A17 -> 11 | B18: Teofilo Ibañez Soliz | C18: Tarija | H18: =SUM(D18:G18) -> 0 | O18: =SUM(I18:N18) -> 0 | V18: =SUM(P18:U18) -> 0 | AC18: =SUM(W18:AB18) -> 0 | AH18: =SUM(AD18:AG18) -> 0 | AI18: =+H18+O18+V18+AH18 -> 0
A19: =1+A18 -> 12 | B19: Elsa Romay Padilla | C19: Uyuni | H19: =SUM(D19:G19) -> 0 | O19: =SUM(I19:N19) -> 0 | V19: =SUM(P19:U19) -> 0 | AC19: =SUM(W19:AB19) -> 0 | AH19: =SUM(AD19:AG19) -> 0 | AI19: =+H19+O19+V19+AH19 -> 0
A20: =1+A19 -> 13 | B20: Jorge Luis Vedia Arancibia | C20: Chuquisaca - Prov | H20: =SUM(D20:G20) -> 0 | O20: =SUM(I20:N20) -> 0 | V20: =SUM(P20:U20) -> 0 | AC20: =SUM(W20:AB20) -> 0 | AH20: =SUM(AD20:AG20) -> 0 | AI20: =+H20+O20+V20+AH20 -> 0
A21: =1+A20 -> 14 | B21: Celina Cruz Mendez | C21: Chuquisaca - Prov | H21: =SUM(D21:G21) -> 0 | O21: =SUM(I21:N21) -> 0 | V21: =SUM(P21:U21) -> 0 | AC21: =SUM(W21:AB21) -> 0 | AH21: =SUM(AD21:AG21) -> 0 | AI21: =+H21+O21+V21+AH21 -> 0
A22: =1+A28 -> 20 | B22: Marlene Paicho | C22: Ruta Colquechaca | H22: =SUM(D22:G22) -> 0 | O22: =SUM(I22:N22) -> 0 | V22: =SUM(P22:U22) -> 0 | AC22: =SUM(W22:AB22) -> 0 | AH22: =SUM(AD22:AG22) -> 0 | AI22: =H22+O22+V22+AH22 -> 0
A23: TOTAL CLIENTES MOROSOS | G23: =SUM(G8:G22) -> 0 | H23: =SUM(D23:G23) -> 0 | I23: =SUM(I8:I22) -> 0 | J23: =SUM(J8:J22) -> 0 | K23: =SUM(K8:K22) -> 0 | L23: =SUM(L8:L22) -> 0 | M23: =SUM(M8:M22) -> 0 | N23: =SUM(N8:N22) -> 0 | O23: =SUM(I23:N23) -> 0 | P23: =SUM(P8:P22) -> 0 | Q23: =SUM(Q8:Q22) -> 0 | R23: =SUM(R8:R22) -> 0 | S23: =SUM(S8:S22) -> 0 | T23: =SUM(T8:T22) -> 0 | U23: =SUM(U8:U22) -> 0 | V23: =SUM(P23:U23) -> 0 | W23: =SUM(W8:W22) -> 0 | X23: =SUM(X8:X22) -> 0 | Y23: =SUM(Y8:Y22) -> 0 | Z23: =SUM(Z8:Z22) -> 0 | AA23: =SUM(AA8:AA22) -> 0 | AB23: =SUM(AB8:AB22) -> 0 | AC23: =SUM(W23:AB23) -> 0 | AD23: =SUM(AD8:AD22) -> 0 | AG23: =SUM(AG8:AG22) -> 0 | AH23: =SUM(AD23:AG23) -> 0 | AI23: =SUM(AI8:AI22) -> 0
A24: =1+A21 -> 15 | B24: EMAPA NACIONAL | C24: NACIONAL | H24: =SUM(D24:G24) -> 0 | O24: =SUM(I24:N24) -> 0 | V24: =SUM(P24:U24) -> 0 | AC24: =SUM(W24:AB24) -> 0 | AH24: =SUM(AD24:AG24) -> 0 | AI24: =H24+O24+V24+AC24+AH24 -> 0
A25: =1+A24 -> 16 | B25: Gustavo Tellez Ugarte | C25: Santa Cruz | H25: =SUM(D25:G25) -> 0 | O25: =SUM(I25:N25) -> 0 | V25: =SUM(P25:U25) -> 0 | AC25: =SUM(W25:AB25) -> 0 | AH25: =SUM(AD25:AG25) -> 0 | AI25: =H25+O25+V25+AC25+AH25 -> 0
A26: =1+A25 -> 17 | B26: Cristhian Murillo | C26: Sucre | H26: =SUM(D26:G26) -> 0 | O26: =SUM(I26:N26) -> 0 | V26: =SUM(P26:U26) -> 0 | AC26: =SUM(W26:AB26) -> 0 | AG26: 241000 | AH26: =SUM(AD26:AG26) -> 241000 | AI26: =H26+O26+V26+AC26+AH26 -> 241000
A27: =1+A26 -> 18 | B27: Sebastian Miranda | C27: Oruro | H27: =SUM(D27:G27) -> 0 | O27: =SUM(I27:N27) -> 0 | V27: =SUM(P27:U27) -> 0 | AC27: =SUM(W27:AB27) -> 0 | AH27: =SUM(AD27:AG27) -> 0 | AI27: =H27+O27+V27+AC27+AH27 -> 0
A28: =1+A27 -> 19 | B28: Norha Choque Talavera | C28: Potosí | H28: =SUM(D28:G28) -> 0 | O28: =SUM(I28:N28) -> 0 | V28: =SUM(P28:U28) -> 0 | AC28: =SUM(W28:AB28) -> 0 | AH28: =SUM(AD28:AG28) -> 0 | AI28: =H28+O28+V28+AC28+AH28 -> 0
A29: =1+A28 -> 20 | B29: Orlando Aldunate M. | C29: Tarija | H29: =SUM(D29:G29) -> 0 | O29: =SUM(I29:N29) -> 0 | V29: =SUM(P29:U29) -> 0 | AC29: =SUM(W29:AB29) -> 0 | AG29: 128559.5 | AH29: =SUM(AD29:AG29) -> 128559.5 | AI29: =H29+O29+V29+AC29+AH29 -> 128559.5
A30: =1+A29 -> 21 | B30: Fausto Condori | C30: Cochabamba | H30: =SUM(D30:G30) -> 0 | O30: =SUM(I30:N30) -> 0 | V30: =SUM(P30:U30) -> 0 | AC30: =SUM(W30:AB30) -> 0 | AH30: =SUM(AD30:AG30) -> 0 | AI30: =H30+O30+V30+AC30+AH30 -> 0
A31: =1+A30 -> 22 | B31: Flora Yapuchura | C31: La Paz | H31: =SUM(D31:G31) -> 0 | O31: =SUM(I31:N31) -> 0 | V31: =SUM(P31:U31) -> 0 | AC31: =SUM(W31:AB31) -> 0 | AH31: =SUM(AD31:AG31) -> 0 | AI31: =H31+O31+V31+AC31+AH31 -> 0
A32: =1+A31 -> 23 | B32: Willy Quispe | C32: El Alto | H32: =SUM(D32:G32) -> 0 | O32: =SUM(I32:N32) -> 0 | V32: =SUM(P32:U32) -> 0 | AC32: =SUM(W32:AB32) -> 0 | AH32: =SUM(AD32:AG32) -> 0 | AI32: =H32+O32+V32+AC32+AH32 -> 0
A33: =1+A32 -> 24 | B33: Andrez Lopez | C33: Potosí | H33: =SUM(D33:G33) -> 0 | O33: =SUM(I33:N33) -> 0 | V33: =SUM(P33:U33) -> 0 | AC33: =SUM(W33:AB33) -> 0 | AH33: =SUM(AD33:AG33) -> 0 | AI33: =H33+O33+V33+AC33+AH33 -> 0
A34: =1+A33 -> 25 | B34: Miguel Angel Mora | C34: Potosí | H34: =SUM(D34:G34) -> 0 | O34: =SUM(I34:N34) -> 0 | V34: =SUM(P34:U34) -> 0 | AC34: =SUM(W34:AB34) -> 0 | AH34: =SUM(AD34:AG34) -> 0 | AI34: =H34+O34+V34+AC34+AH34 -> 0
A35: =1+A34 -> 26 | B35: GAMS Desarrollo Productivo | C35: Sucre | H35: =SUM(D35:G35) -> 0 | O35: =SUM(I35:N35) -> 0 | V35: =SUM(P35:U35) -> 0 | AC35: =SUM(W35:AB35) -> 0 | AH35: =SUM(AD35:AG35) -> 0 | AI35: =H35+O35+V35+AC35+AH35 -> 0
A36: =1+A35 -> 27 | B36: GAMS Direccion Administrativa | C36: Sucre | H36: =SUM(D36:G36) -> 0 | O36: =SUM(I36:N36) -> 0 | V36: =SUM(P36:U36) -> 0 | AC36: =SUM(W36:AB36) -> 0 | AH36: =SUM(AD36:AG36) -> 0 | AI36: =H36+O36+V36+AC36+AH36 -> 0
A37: =1+A36 -> 28 | B37: Carmen Cruz | C37: Potosí | H37: =SUM(D37:G37) -> 0 | O37: =SUM(I37:N37) -> 0 | V37: =SUM(P37:U37) -> 0 | AC37: =SUM(W37:AB37) -> 0 | AG37: 77074 | AH37: =SUM(AD37:AG37) -> 77074 | AI37: =H37+O37+V37+AC37+AH37 -> 77074
A38: =1+A37 -> 29 | B38: Judith | C38: Cochabamba | H38: =SUM(D38:G38) -> 0 | O38: =SUM(I38:N38) -> 0 | V38: =SUM(P38:U38) -> 0 | AC38: =SUM(W38:AB38) -> 0 | AH38: =SUM(AD38:AG38) -> 0 | AI38: =H38+O38+V38+AC38+AH38 -> 0
A39: =1+A38 -> 30 | B39: Kevin | C39: Oruro | H39: =SUM(D39:G39) -> 0 | O39: =SUM(I39:N39) -> 0 | V39: =SUM(P39:U39) -> 0 | AC39: =SUM(W39:AB39) -> 0 | AH39: =SUM(AD39:AG39) -> 0 | AI39: =H39+O39+V39+AC39+AH39 -> 0
A40: =1+A39 -> 31 | B40: Jorge Saavedra | C40: Tupiza | H40: =SUM(D40:G40) -> 0 | O40: =SUM(I40:N40) -> 0 | V40: =SUM(P40:U40) -> 0 | AC40: =SUM(W40:AB40) -> 0 | AH40: =SUM(AD40:AG40) -> 0 | AI40: =H40+O40+V40+AC40+AH40 -> 0
A41: =1+A40 -> 32 | B41: Jenrry | C41: Chile | H41: =SUM(D41:G41) -> 0 | O41: =SUM(I41:N41) -> 0 | V41: =SUM(P41:U41) -> 0 | AC41: =SUM(W41:AB41) -> 0 | AG41: 292565 | AH41: =SUM(AD41:AG41) -> 292565 | AI41: =H41+O41+V41+AC41+AH41 -> 292565
A42: =1+A41 -> 33 | B42: Eddy | C42: Chile | H42: =SUM(D42:G42) -> 0 | O42: =SUM(I42:N42) -> 0 | V42: =SUM(P42:U42) -> 0 | AC42: =SUM(W42:AB42) -> 0 | AH42: =SUM(AD42:AG42) -> 0 | AI42: =H42+O42+V42+AC42+AH42 -> 0
...

Sheet RECAU. MAYO 2025
A3: CUENTAS POR COBRAR A CLIENTES
A4: GESTION 2023 - 2024
A5: MAYO - 2025
A6: Nº | B6: DISTRIBUIDOR | C6: DEPARTAMENTO | AI6: TOTAL MES
D7: 1 | E7: 2 | F7: 3 | G7: 4 | H7: Semana 1 | I7: 6 | J7: 7 | K7: 8 | L7: 9 | M7: 10 | N7: 11 | O7: Semana 2 | P7: 13 | Q7: 14 | R7: 15 | S7: 16 | T7: 17 | U7: 18 | V7: Semana 3 | W7: 20 | X7: 21 | Y7: 22 | Z7: 23 | AA7: 24 | AB7: 25 | AC7: Semana 4 | AD7: 27 | AE7: 28 | AF7: 29 | AG7: 28 | AH7: Semana 4
A8: 1 | B8: Fabricio Tapia Castedo | C8: Cochabamba | H8: =SUM(D8:G8) -> 0 | O8: =SUM(I8:N8) -> 0 | V8: =SUM(P8:U8) -> 0 | AC8: =SUM(W8:AB8) -> 0 | AH8: =SUM(AD8:AG8) -> 0 | AI8: =+H8+O8+V8+AH8 -> 0
A9: =1+A8 -> 2 | B9: Edwin Fernandez Chirinos | C9: El Alto | H9: =SUM(D9:G9) -> 0 | O9: =SUM(I9:N9) -> 0 | V9: =SUM(P9:U9) -> 0 | AC9: =SUM(W9:AB9) -> 0 | AH9: =SUM(AD9:AG9) -> 0 | AI9: =+H9+O9+V9+AH9 -> 0
A10: =1+A9 -> 3 | B10: Javier Caceres | C10: Cochabamba | H10: =SUM(D10:G10) -> 0 | O10: =SUM(I10:N10) -> 0 | V10: =SUM(P10:U10) -> 0 | AC10: =SUM(W10:AB10) -> 0 | AH10: =SUM(AD10:AG10) -> 0 | AI10: =+H10+O10+V10+AH10 -> 0
A11: =1+A10 -> 4 | B11: Juan Carlos Torrez Ayarde | C11: Tarija | H11: =SUM(D11:G11) -> 0 | O11: =SUM(I11:N11) -> 0 | V11: =SUM(P11:U11) -> 0 | AC11: =SUM(W11:AB11) -> 0 | AH11: =SUM(AD11:AG11) -> 0 | AI11: =+H11+O11+V11+AH11 -> 0
A12: =1+A11 -> 5 | B12: Carol Alejandra Noya | C12: Tarija | H12: =SUM(D12:G12) -> 0 | O12: =SUM(I12:N12) -> 0 | V12: =SUM(P12:U12) -> 0 | AC12: =SUM(W12:AB12) -> 0 | AH12: =SUM(AD12:AG12) -> 0 | AI12: =+H12+O12+V12+AH12 -> 0
A13: =1+A12 -> 6 | B13: Luis Alberto Chipana Peña | C13: Cochabamba | H13: =SUM(D13:G13) -> 0 | O13: =SUM(I13:N13) -> 0 | V13: =SUM(P13:U13) -> 0 | AC13: =SUM(W13:AB13) -> 0 | AH13: =SUM(AD13:AG13) -> 0 | AI13: =+H13+O13+V13+AH13 -> 0
A14: =1+A13 -> 7 | B14: Franz Carlos Alanez Flores | C14: El Alto | H14: =SUM(D14:G14) -> 0 | O14: =SUM(I14:N14) -> 0 | V14: =SUM(P14:U14) -> 0 | AC14: =SUM(W14:AB14) -> 0 | AH14: =SUM(AD14:AG14) -> 0 | AI14: =+H14+O14+V14+AH14 -> 0
A15: =1+A14 -> 8 | B15: Andrés Miguel Paniagua | C15: Oruro | H15: =SUM(D15:G15) -> 0 | O15: =SUM(I15:N15) -> 0 | V15: =SUM(P15:U15) -> 0 | AC15: =SUM(W15:AB15) -> 0 | AH15: =SUM(AD15:AG15) -> 0 | AI15: =+H15+O15+V15+AH15 -> 0
A16: =1+A15 -> 9 | B16: Alex Rolando Fernandez H. | C16: Oruro | H16: =SUM(D16:G16) -> 0 | O16: =SUM(I16:N16) -> 0 | V16: =SUM(P16:U16) -> 0 | AC16: =SUM(W16:AB16) -> 0 | AH16: =SUM(AD16:AG16) -> 0 | AI16: =+H16+O16+V16+AH16 -> 0
A17: =1+A16 -> 10 | B17: Franklin Ever Viveros | C17: Potosí | H17: =SUM(D17:G17) -> 0 | O17: =SUM(I17:N17) -> 0 | V17: =SUM(P17:U17) -> 0 | AC17: =SUM(W17:AB17) -> 0 | AH17: =SUM(AD17:AG17) -> 0 | AI17: =+H17+O17+V17+AH17 -> 0
A18: =1+A17 -> 11 | B18: Teofilo Ibañez Soliz | C18: Tarija | H18: =SUM(D18:G18) -> 0 | O18: =SUM(I18:N18) -> 0 | V18: =SUM(P18:U18) -> 0 | AC18: =SUM(W18:AB18) -> 0 | AH18: =SUM(AD18:AG18) -> 0 | AI18: =+H18+O18+V18+AH18 -> 0
A19: =1+A18 -> 12 | B19: Elsa Romay Padilla | C19: Uyuni | H19: =SUM(D19:G19) -> 0 | O19: =SUM(I19:N19) -> 0 | V19: =SUM(P19:U19) -> 0 | AC19: =SUM(W19:AB19) -> 0 | AH19: =SUM(AD19:AG19) -> 0 | AI19: =+H19+O19+V19+AH19 -> 0
A20: =1+A19 -> 13 | B20: Jorge Luis Vedia Arancibia | C20: Chuquisaca - Prov | H20: =SUM(D20:G20) -> 0 | O20: =SUM(I20:N20) -> 0 | V20: =SUM(P20:U20) -> 0 | AC20: =SUM(W20:AB20) -> 0 | AH20: =SUM(AD20:AG20) -> 0 | AI20: =+H20+O20+V20+AH20 -> 0
A21: =1+A20 -> 14 | B21: Celina Cruz Mendez | C21: Chuquisaca - Prov | H21: =SUM(D21:G21) -> 0 | O21: =SUM(I21:N21) -> 0 | V21: =SUM(P21:U21) -> 0 | AC21: =SUM(W21:AB21) -> 0 | AH21: =SUM(AD21:AG21) -> 0 | AI21: =+H21+O21+V21+AH21 -> 0
A22: =1+A28 -> 20 | B22: Marlene Paicho | C22: Ruta Colquechaca | H22: =SUM(D22:G22) -> 0 | O22: =SUM(I22:N22) -> 0 | V22: =SUM(P22:U22) -> 0 | AC22: =SUM(W22:AB22) -> 0 | AH22: =SUM(AD22:AG22) -> 0 | AI22: =H22+O22+V22+AH22 -> 0
A23: TOTAL CLIENTES MOROSOS | G23: =SUM(G8:G22) -> 0 | H23: =SUM(D23:G23) -> 0 | I23: =SUM(I8:I22) -> 0 | J23: =SUM(J8:J22) -> 0 | K23: =SUM(K8:K22) -> 0 | L23: =SUM(L8:L22) -> 0 | M23: =SUM(M8:M22) -> 0 | N23: =SUM(N8:N22) -> 0 | O23: =SUM(I23:N23) -> 0 | P23: =SUM(P8:P22) -> 0 | Q23: =SUM(Q8:Q22) -> 0 | R23: =SUM(R8:R22) -> 0 | S23: =SUM(S8:S22) -> 0 | T23: =SUM(T8:T22) -> 0 | U23: =SUM(U8:U22) -> 0 | V23: =SUM(P23:U23) -> 0 | W23: =SUM(W8:W22) -> 0 | X23: =SUM(X8:X22) -> 0 | Y23: =SUM(Y8:Y22) -> 0 | Z23: =SUM(Z8:Z22) -> 0 | AA23: =SUM(AA8:AA22) -> 0 | AB23: =SUM(AB8:AB22) -> 0 | AC23: =SUM(W23:AB23) -> 0 | AD23: =SUM(AD8:AD22) -> 0 | AG23: =SUM(AG8:AG22) -> 0 | AH23: =SUM(AD23:AG23) -> 0 | AI23: =SUM(AI8:AI22) -> 0
A24: =1+A21 -> 15 | B24: EMAPA NACIONAL | C24: NACIONAL | H24: =SUM(D24:G24) -> 0 | O24: =SUM(I24:N24) -> 0 | V24: =SUM(P24:U24) -> 0 | AC24: =SUM(W24:AB24) -> 0 | AH24: =SUM(AD24:AG24) -> 0 | AI24: =H24+O24+V24+AC24+AH24 -> 0
A25: =1+A24 -> 16 | B25: Gustavo Tellez Ugarte | C25: Santa Cruz | H25: =SUM(D25:G25) -> 0 | O25: =SUM(I25:N25) -> 0 | V25: =SUM(P25:U25) -> 0 | AC25: =SUM(W25:AB25) -> 0 | AH25: =SUM(AD25:AG25) -> 0 | AI25: =H25+O25+V25+AC25+AH25 -> 0
A26: =1+A25 -> 17 | B26: Cristhian Murillo | C26: Sucre | H26: =SUM(D26:G26) -> 0 | O26: =SUM(I26:N26) -> 0 | V26: =SUM(P26:U26) -> 0 | AC26: =SUM(W26:AB26) -> 0 | AG26: =+'Cristhian Murillo'!L27 -> 205000 | AH26: =SUM(AD26:AG26) -> 205000 | AI26: =H26+O26+V26+AC26+AH26 -> 205000
A27: =1+A26 -> 18 | B27: Sebastian Miranda | C27: Oruro | H27: =SUM(D27:G27) -> 0 | O27: =SUM(I27:N27) -> 0 | V27: =SUM(P27:U27) -> 0 | AC27: =SUM(W27:AB27) -> 0 | AH27: =SUM(AD27:AG27) -> 0 | AI27: =H27+O27+V27+AC27+AH27 -> 0
A28: =1+A27 -> 19 | B28: Norha Choque Talavera | C28: Potosí | H28: =SUM(D28:G28) -> 0 | O28: =SUM(I28:N28) -> 0 | V28: =SUM(P28:U28) -> 0 | AC28: =SUM(W28:AB28) -> 0 | AH28: =SUM(AD28:AG28) -> 0 | AI28: =H28+O28+V28+AC28+AH28 -> 0
A29: =1+A28 -> 20 | B29: Orlando Aldunate M. | C29: Tarija | H29: =SUM(D29:G29) -> 0 | O29: =SUM(I29:N29) -> 0 | V29: =SUM(P29:U29) -> 0 | AC29: =SUM(W29:AB29) -> 0 | AG29: =+'Orlando Aldunate'!L19 -> 138108.5 | AH29: =SUM(AD29:AG29) -> 138108.5 | AI29: =H29+O29+V29+AC29+AH29 -> 138108.5
A30: =1+A29 -> 21 | B30: Fausto Condori | C30: Cochabamba | H30: =SUM(D30:G30) -> 0 | O30: =SUM(I30:N30) -> 0 | V30: =SUM(P30:U30) -> 0 | AC30: =SUM(W30:AB30) -> 0 | AH30: =SUM(AD30:AG30) -> 0 | AI30: =H30+O30+V30+AC30+AH30 -> 0
A31: =1+A30 -> 22 | B31: Flora Yapuchura | C31: La Paz | H31: =SUM(D31:G31) -> 0 | O31: =SUM(I31:N31) -> 0 | V31: =SUM(P31:U31) -> 0 | AC31: =SUM(W31:AB31) -> 0 | AH31: =SUM(AD31:AG31) -> 0 | AI31: =H31+O31+V31+AC31+AH31 -> 0
A32: =1+A31 -> 23 | B32: Willy Quispe | C32: El Alto | H32: =SUM(D32:G32) -> 0 | O32: =SUM(I32:N32) -> 0 | V32: =SUM(P32:U32) -> 0 | AC32: =SUM(W32:AB32) -> 0 | AH32: =SUM(AD32:AG32) -> 0 | AI32: =H32+O32+V32+AC32+AH32 -> 0
A33: =1+A32 -> 24 | B33: Andrez Lopez | C33: Potosí | H33: =SUM(D33:G33) -> 0 | O33: =SUM(I33:N33) -> 0 | V33: =SUM(P33:U33) -> 0 | AC33: =SUM(W33:AB33) -> 0 | AH33: =SUM(AD33:AG33) -> 0 | AI33: =H33+O33+V33+AC33+AH33 -> 0
A34: =1+A33 -> 25 | B34: Miguel Angel Mora | C34: Potosí | H34: =SUM(D34:G34) -> 0 | O34: =SUM(I34:N34) -> 0 | V34: =SUM(P34:U34) -> 0 | AC34: =SUM(W34:AB34) -> 0 | AH34: =SUM(AD34:AG34) -> 0 | AI34: =H34+O34+V34+AC34+AH34 -> 0
A35: =1+A34 -> 26 | B35: GAMS Desarrollo Productivo | C35: Sucre | H35: =SUM(D35:G35) -> 0 | O35: =SUM(I35:N35) -> 0 | V35: =SUM(P35:U35) -> 0 | AC35: =SUM(W35:AB35) -> 0 | AH35: =SUM(AD35:AG35) -> 0 | AI35: =H35+O35+V35+AC35+AH35 -> 0
A36: =1+A35 -> 27 | B36: GAMS Direccion Administrativa | C36: Sucre | H36: =SUM(D36:G36) -> 0 | O36: =SUM(I36:N36) -> 0 | V36: =SUM(P36:U36) -> 0 | AC36: =SUM(W36:AB36) -> 0 | AH36: =SUM(AD36:AG36) -> 0 | AI36: =H36+O36+V36+AC36+AH36 -> 0
A37: =1+A36 -> 28 | B37: Carmen Cruz | C37: Potosí | H37: =SUM(D37:G37) -> 0 | O37: =SUM(I37:N37) -> 0 | V37: =SUM(P37:U37) -> 0 | AC37: =SUM(W37:AB37) -> 0 | AG37: =+#REF! -> #REF! | AH37: =SUM(AD37:AG37) -> #REF! | AI37: =H37+O37+V37+AC37+AH37 -> #REF!
A38: =1+A37 -> 29 | B38: Judith | C38: Cochabamba | H38: =SUM(D38:G38) -> 0 | O38: =SUM(I38:N38) -> 0 | V38: =SUM(P38:U38) -> 0 | AC38: =SUM(W38:AB38) -> 0 | AH38: =SUM(AD38:AG38) -> 0 | AI38: =H38+O38+V38+AC38+AH38 -> 0
A39: =1+A38 -> 30 | B39: Kevin | C39: Oruro | H39: =SUM(D39:G39) -> 0 | O39: =SUM(I39:N39) -> 0 | V39: =SUM(P39:U39) -> 0 | AC39: =SUM(W39:AB39) -> 0 | AH39: =SUM(AD39:AG39) -> 0 | AI39: =H39+O39+V39+AC39+AH39 -> 0
A40: =1+A39 -> 31 | B40: Jorge Saavedra | C40: Tupiza | H40: =SUM(D40:G40) -> 0 | O40: =SUM(I40:N40) -> 0 | V40: =SUM(P40:U40) -> 0 | AC40: =SUM(W40:AB40) -> 0 | AH40: =SUM(AD40:AG40) -> 0 | AI40: =H40+O40+V40+AC40+AH40 -> 0
A41: =1+A40 -> 32 | B41: Jenrry | C41: Chile | H41: =SUM(D41:G41) -> 0 | O41: =SUM(I41:N41) -> 0 | V41: =SUM(P41:U41) -> 0 | AC41: =SUM(W41:AB41) -> 0 | AH41: =SUM(AD41:AG41) -> 0 | AI41: =H41+O41+V41+AC41+AH41 -> 0
A42: =1+A41 -> 33 | B42: Eddy | C42: Chile | H42: =SUM(D42:G42) -> 0 | O42: =SUM(I42:N42) -> 0 | V42: =SUM(P42:U42) -> 0 | AC42: =SUM(W42:AB42) -> 0 | AH42: =SUM(AD42:AG42) -> 0 | AI42: =H42+O42+V42+AC42+AH42 -> 0
...

Sheet RECAU. JUNIO 2025
A3: CUENTAS POR COBRAR A CLIENTES
A4: GESTION 2023 - 2024
A5: JUNIO - 2025
A6: Nº | B6: DISTRIBUIDOR | C6: DEPARTAMENTO | AI6: TOTAL MES
D7: 1 | E7: 2 | F7: 3 | G7: 4 | H7: Semana 1 | I7: 6 | J7: 7 | K7: 8 | L7: 9 | M7: 10 | N7: 11 | O7: Semana 2 | P7: 13 | Q7: 14 | R7: 15 | S7: 16 | T7: 17 | U7: 18 | V7: Semana 3 | W7: 20 | X7: 21 | Y7: 22 | Z7: 23 | AA7: 24 | AB7: 25 | AC7: Semana 4 | AD7: 27 | AE7: 28 | AF7: 29 | AG7: 28 | AH7: Semana 4
A8: 1 | B8: Fabricio Tapia Castedo | C8: Cochabamba | H8: =SUM(D8:G8) -> 0 | O8: =SUM(I8:N8) -> 0 | V8: =SUM(P8:U8) -> 0 | AC8: =SUM(W8:AB8) -> 0 | AH8: =SUM(AD8:AG8) -> 0 | AI8: =+H8+O8+V8+AH8 -> 0
A9: =1+A8 -> 2 | B9: Edwin Fernandez Chirinos | C9: El Alto | H9: =SUM(D9:G9) -> 0 | O9: =SUM(I9:N9) -> 0 | V9: =SUM(P9:U9) -> 0 | AC9: =SUM(W9:AB9) -> 0 | AH9: =SUM(AD9:AG9) -> 0 | AI9: =+H9+O9+V9+AH9 -> 0
A10: =1+A9 -> 3 | B10: Javier Caceres | C10: Cochabamba | H10: =SUM(D10:G10) -> 0 | O10: =SUM(I10:N10) -> 0 | V10: =SUM(P10:U10) -> 0 | AC10: =SUM(W10:AB10) -> 0 | AH10: =SUM(AD10:AG10) -> 0 | AI10: =+H10+O10+V10+AH10 -> 0
A11: =1+A10 -> 4 | B11: Juan Carlos Torrez Ayarde | C11: Tarija | H11: =SUM(D11:G11) -> 0 | O11: =SUM(I11:N11) -> 0 | V11: =SUM(P11:U11) -> 0 | AC11: =SUM(W11:AB11) -> 0 | AH11: =SUM(AD11:AG11) -> 0 | AI11: =+H11+O11+V11+AH11 -> 0
A12: =1+A11 -> 5 | B12: Carol Alejandra Noya | C12: Tarija | H12: =SUM(D12:G12) -> 0 | O12: =SUM(I12:N12) -> 0 | V12: =SUM(P12:U12) -> 0 | AC12: =SUM(W12:AB12) -> 0 | AH12: =SUM(AD12:AG12) -> 0 | AI12: =+H12+O12+V12+AH12 -> 0
A13: =1+A12 -> 6 | B13: Luis Alberto Chipana Peña | C13: Cochabamba | H13: =SUM(D13:G13) -> 0 | O13: =SUM(I13:N13) -> 0 | V13: =SUM(P13:U13) -> 0 | AC13: =SUM(W13:AB13) -> 0 | AH13: =SUM(AD13:AG13) -> 0 | AI13: =+H13+O13+V13+AH13 -> 0
A14: =1+A13 -> 7 | B14: Franz Carlos Alanez Flores | C14: El Alto | H14: =SUM(D14:G14) -> 0 | O14: =SUM(I14:N14) -> 0 | V14: =SUM(P14:U14) -> 0 | AC14: =SUM(W14:AB14) -> 0 | AH14: =SUM(AD14:AG14) -> 0 | AI14: =+H14+O14+V14+AH14 -> 0
A15: =1+A14 -> 8 | B15: Andrés Miguel Paniagua | C15: Oruro | H15: =SUM(D15:G15) -> 0 | O15: =SUM(I15:N15) -> 0 | V15: =SUM(P15:U15) -> 0 | AC15: =SUM(W15:AB15) -> 0 | AH15: =SUM(AD15:AG15) -> 0 | AI15: =+H15+O15+V15+AH15 -> 0
A16: =1+A15 -> 9 | B16: Alex Rolando Fernandez H. | C16: Oruro | H16: =SUM(D16:G16) -> 0 | O16: =SUM(I16:N16) -> 0 | V16: =SUM(P16:U16) -> 0 | AC16: =SUM(W16:AB16) -> 0 | AH16: =SUM(AD16:AG16) -> 0 | AI16: =+H16+O16+V16+AH16 -> 0
A17: =1+A16 -> 10 | B17: Franklin Ever Viveros | C17: Potosí | H17: =SUM(D17:G17) -> 0 | O17: =SUM(I17:N17) -> 0 | V17: =SUM(P17:U17) -> 0 | AC17: =SUM(W17:AB17) -> 0 | AH17: =SUM(AD17:AG17) -> 0 | AI17: =+H17+O17+V17+AH17 -> 0
A18: =1+A17 -> 11 | B18: Teofilo Ibañez Soliz | C18: Tarija | H18: =SUM(D18:G18) -> 0 | O18: =SUM(I18:N18) -> 0 | V18: =SUM(P18:U18) -> 0 | AC18: =SUM(W18:AB18) -> 0 | AH18: =SUM(AD18:AG18) -> 0 | AI18: =+H18+O18+V18+AH18 -> 0
A19: =1+A18 -> 12 | B19: Elsa Romay Padilla | C19: Uyuni | H19: =SUM(D19:G19) -> 0 | O19: =SUM(I19:N19) -> 0 | V19: =SUM(P19:U19) -> 0 | AC19: =SUM(W19:AB19) -> 0 | AH19: =SUM(AD19:AG19) -> 0 | AI19: =+H19+O19+V19+AH19 -> 0
A20: =1+A19 -> 13 | B20: Jorge Luis Vedia Arancibia | C20: Chuquisaca - Prov | H20: =SUM(D20:G20) -> 0 | O20: =SUM(I20:N20) -> 0 | V20: =SUM(P20:U20) -> 0 | AC20: =SUM(W20:AB20) -> 0 | AH20: =SUM(AD20:AG20) -> 0 | AI20: =+H20+O20+V20+AH20 -> 0
A21: =1+A20 -> 14 | B21: Celina Cruz Mendez | C21: Chuquisaca - Prov | H21: =SUM(D21:G21) -> 0 | O21: =SUM(I21:N21) -> 0 | V21: =SUM(P21:U21) -> 0 | AC21: =SUM(W21:AB21) -> 0 | AH21: =SUM(AD21:AG21) -> 0 | AI21: =+H21+O21+V21+AH21 -> 0
A22: =1+A28 -> 20 | B22: Marlene Paicho | C22: Ruta Colquechaca | H22: =SUM(D22:G22) -> 0 | O22: =SUM(I22:N22) -> 0 | V22: =SUM(P22:U22) -> 0 | AC22: =SUM(W22:AB22) -> 0 | AH22: =SUM(AD22:AG22) -> 0 | AI22: =H22+O22+V22+AH22 -> 0
A23: TOTAL CLIENTES MOROSOS | G23: =SUM(G8:G22) -> 0 | H23: =SUM(D23:G23) -> 0 | I23: =SUM(I8:I22) -> 0 | J23: =SUM(J8:J22) -> 0 | K23: =SUM(K8:K22) -> 0 | L23: =SUM(L8:L22) -> 0 | M23: =SUM(M8:M22) -> 0 | N23: =SUM(N8:N22) -> 0 | O23: =SUM(I23:N23) -> 0 | P23: =SUM(P8:P22) -> 0 | Q23: =SUM(Q8:Q22) -> 0 | R23: =SUM(R8:R22) -> 0 | S23: =SUM(S8:S22) -> 0 | T23: =SUM(T8:T22) -> 0 | U23: =SUM(U8:U22) -> 0 | V23: =SUM(P23:U23) -> 0 | W23: =SUM(W8:W22) -> 0 | X23: =SUM(X8:X22) -> 0 | Y23: =SUM(Y8:Y22) -> 0 | Z23: =SUM(Z8:Z22) -> 0 | AA23: =SUM(AA8:AA22) -> 0 | AB23: =SUM(AB8:AB22) -> 0 | AC23: =SUM(W23:AB23) -> 0 | AD23: =SUM(AD8:AD22) -> 0 | AG23: =SUM(AG8:AG22) -> 0 | AH23: =SUM(AD23:AG23) -> 0 | AI23: =SUM(AI8:AI22) -> 0
A24: =1+A21 -> 15 | B24: EMAPA NACIONAL | C24: NACIONAL | H24: =SUM(D24:G24) -> 0 | O24: =SUM(I24:N24) -> 0 | V24: =SUM(P24:U24) -> 0 | AC24: =SUM(W24:AB24) -> 0 | AH24: =SUM(AD24:AG24) -> 0 | AI24: =H24+O24+V24+AC24+AH24 -> 0
A25: =1+A24 -> 16 | B25: Gustavo Tellez Ugarte | C25: Santa Cruz | H25: =SUM(D25:G25) -> 0 | O25: =SUM(I25:N25) -> 0 | V25: =SUM(P25:U25) -> 0 | AC25: =SUM(W25:AB25) -> 0 | AG25: 85974 | AH25: =SUM(AD25:AG25) -> 85974 | AI25: =H25+O25+V25+AC25+AH25 -> 85974
A26: =1+A25 -> 17 | B26: Cristhian Murillo | C26: Sucre | H26: =SUM(D26:G26) -> 0 | O26: =SUM(I26:N26) -> 0 | V26: =SUM(P26:U26) -> 0 | AC26: =SUM(W26:AB26) -> 0 | AG26: 100000 | AH26: =SUM(AD26:AG26) -> 100000 | AI26: =H26+O26+V26+AC26+AH26 -> 100000
A27: =1+A26 -> 18 | B27: Sebastian Miranda | C27: Oruro | H27: =SUM(D27:G27) -> 0 | O27: =SUM(I27:N27) -> 0 | V27: =SUM(P27:U27) -> 0 | AC27: =SUM(W27:AB27) -> 0 | AH27: =SUM(AD27:AG27) -> 0 | AI27: =H27+O27+V27+AC27+AH27 -> 0
A28: =1+A27 -> 19 | B28: Norha Choque Talavera | C28: Potosí | H28: =SUM(D28:G28) -> 0 | O28: =SUM(I28:N28) -> 0 | V28: =SUM(P28:U28) -> 0 | AC28: =SUM(W28:AB28) -> 0 | AH28: =SUM(AD28:AG28) -> 0 | AI28: =H28+O28+V28+AC28+AH28 -> 0
A29: =1+A28 -> 20 | B29: Orlando Aldunate M. | C29: Tarija | H29: =SUM(D29:G29) -> 0 | O29: =SUM(I29:N29) -> 0 | V29: =SUM(P29:U29) -> 0 | AC29: =SUM(W29:AB29) -> 0 | AH29: =SUM(AD29:AG29) -> 0 | AI29: =H29+O29+V29+AC29+AH29 -> 0
A30: =1+A29 -> 21 | B30: Fausto Condori | C30: Cochabamba | H30: =SUM(D30:G30) -> 0 | O30: =SUM(I30:N30) -> 0 | V30: =SUM(P30:U30) -> 0 | AC30: =SUM(W30:AB30) -> 0 | AH30: =SUM(AD30:AG30) -> 0 | AI30: =H30+O30+V30+AC30+AH30 -> 0
A31: =1+A30 -> 22 | B31: Flora Yapuchura | C31: La Paz | H31: =SUM(D31:G31) -> 0 | O31: =SUM(I31:N31) -> 0 | V31: =SUM(P31:U31) -> 0 | AC31: =SUM(W31:AB31) -> 0 | AH31: =SUM(AD31:AG31) -> 0 | AI31: =H31+O31+V31+AC31+AH31 -> 0
A32: =1+A31 -> 23 | B32: Willy Quispe | C32: El Alto | H32: =SUM(D32:G32) -> 0 | O32: =SUM(I32:N32) -> 0 | V32: =SUM(P32:U32) -> 0 | AC32: =SUM(W32:AB32) -> 0 | AH32: =SUM(AD32:AG32) -> 0 | AI32: =H32+O32+V32+AC32+AH32 -> 0
A33: =1+A32 -> 24 | B33: Andrez Lopez | C33: Potosí | H33: =SUM(D33:G33) -> 0 | O33: =SUM(I33:N33) -> 0 | V33: =SUM(P33:U33) -> 0 | AC33: =SUM(W33:AB33) -> 0 | AH33: =SUM(AD33:AG33) -> 0 | AI33: =H33+O33+V33+AC33+AH33 -> 0
A34: =1+A33 -> 25 | B34: Miguel Angel Mora | C34: Potosí | H34: =SUM(D34:G34) -> 0 | O34: =SUM(I34:N34) -> 0 | V34: =SUM(P34:U34) -> 0 | AC34: =SUM(W34:AB34) -> 0 | AH34: =SUM(AD34:AG34) -> 0 | AI34: =H34+O34+V34+AC34+AH34 -> 0
A35: =1+A34 -> 26 | B35: GAMS Desarrollo Productivo | C35: Sucre | H35: =SUM(D35:G35) -> 0 | O35: =SUM(I35:N35) -> 0 | V35: =SUM(P35:U35) -> 0 | AC35: =SUM(W35:AB35) -> 0 | AH35: =SUM(AD35:AG35) -> 0 | AI35: =H35+O35+V35+AC35+AH35 -> 0
A36: =1+A35 -> 27 | B36: GAMS Direccion Administrativa | C36: Sucre | H36: =SUM(D36:G36) -> 0 | O36: =SUM(I36:N36) -> 0 | V36: =SUM(P36:U36) -> 0 | AC36: =SUM(W36:AB36) -> 0 | AH36: =SUM(AD36:AG36) -> 0 | AI36: =H36+O36+V36+AC36+AH36 -> 0
A37: =1+A36 -> 28 | B37: Carmen Cruz | C37: Potosí | H37: =SUM(D37:G37) -> 0 | O37: =SUM(I37:N37) -> 0 | V37: =SUM(P37:U37) -> 0 | AC37: =SUM(W37:AB37) -> 0 | AG37: 148090 | AH37: =SUM(AD37:AG37) -> 148090 | AI37: =H37+O37+V37+AC37+AH37 -> 148090
A38: =1+A37 -> 29 | B38: Judith | C38: Cochabamba | H38: =SUM(D38:G38) -> 0 | O38: =SUM(I38:N38) -> 0 | V38: =SUM(P38:U38) -> 0 | AC38: =SUM(W38:AB38) -> 0 | AH38: =SUM(AD38:AG38) -> 0 | AI38: =H38+O38+V38+AC38+AH38 -> 0
A39: =1+A38 -> 30 | B39: Kevin | C39: Oruro | H39: =SUM(D39:G39) -> 0 | O39: =SUM(I39:N39) -> 0 | V39: =SUM(P39:U39) -> 0 | AC39: =SUM(W39:AB39) -> 0 | AH39: =SUM(AD39:AG39) -> 0 | AI39: =H39+O39+V39+AC39+AH39 -> 0
A40: =1+A39 -> 31 | B40: Jorge Saavedra | C40: Tupiza | H40: =SUM(D40:G40) -> 0 | O40: =SUM(I40:N40) -> 0 | V40: =SUM(P40:U40) -> 0 | AC40: =SUM(W40:AB40) -> 0 | AH40: =SUM(AD40:AG40) -> 0 | AI40: =H40+O40+V40+AC40+AH40 -> 0
A41: =1+A40 -> 32 | B41: Jenrry | C41: Chile | H41: =SUM(D41:G41) -> 0 | O41: =SUM(I41:N41) -> 0 | V41: =SUM(P41:U41) -> 0 | AC41: =SUM(W41:AB41) -> 0 | AG41: 200633.6 | AH41: =SUM(AD41:AG41) -> 200633.6 | AI41: =H41+O41+V41+AC41+AH41 -> 200633.6
A42: =1+A41 -> 33 | B42: Eddy | C42: Chile | H42: =SUM(D42:G42) -> 0 | O42: =SUM(I42:N42) -> 0 | V42: =SUM(P42:U42) -> 0 | AC42: =SUM(W42:AB42) -> 0 | AG42: 436247 | AH42: =SUM(AD42:AG42) -> 436247 | AI42: =H42+O42+V42+AC42+AH42 -> 436247
...

Sheet EMAPA
B2: CUENTAS POR COBRAR
B3: GESTION 2025 - 2026
C5: CLIENTE: | D5: EMAPA NACIONAL
C6: CELULAR:
C7: DESTINO: | D7: TODAS LAS REGIONALES
C8: LINEA DE CREDITO:
B10: NOTA DE VENTA | C10: NOTA DE ENTREGA | D10: FECHA DE DESPACHO | E10: MONTO P/COBRAR | F10: DESTINO | G10: DEPÓSITO en Bs | H10: FECHA DE DEPÓSITO | I10: SALDO | J10: N° FACTURA | K10: OBSERVACION
I11: =+E11-G11 -> 0
I12: =+I11+E12-G12 -> 0
I13: =+I12+E13-G13 -> 0
I14: =+I13+E14-G14 -> 0
I15: =+I14+E15-G15 -> 0
I16: =+I15+E16-G16 -> 0
I17: =+I16+E17-G17 -> 0
I18: =+I17+E18-G18 -> 0
I19: =+I18+E19-G19 -> 0
I20: =+I19+E20-G20 -> 0
I21: =+I20+E21-G21 -> 0
I22: =+I21+E22-G22 -> 0
I23: =+I22+E23-G23 -> 0
... I138: =+I137+E138-G138 -> 0
B139: TOTALES | E139: =SUM(E11:E138) -> 0 | G139: =SUM(G11:G138) -> 0
C140: SALDO POR COBRAR | G140: =+E139-G139 -> 0
C141: LINEA DE CREDITO | G141: 0
C142: SALDO DESPUES DE LA LINEA DE CREDITO | G142: =+G140-G141 -> 0

Sheet RECAU. AGOSTO 2025
A3: CUENTAS POR COBRAR A CLIENTES
A4: GESTION 2023 - 2024
A5: JULIO - 2025
A6: Nº | B6: DISTRIBUIDOR | C6: DEPARTAMENTO | AI6: TOTAL MES
D7: 1 | E7: 2 | F7: 3 | G7: 4 | H7: Semana 1 | I7: 6 | J7: 7 | K7: 8 | L7: 9 | M7: 10 | N7: 11 | O7: Semana 2 | P7: 13 | Q7: 14 | R7: 15 | S7: 16 | T7: 17 | U7: 18 | V7: Semana 3 | W7: 20 | X7: 21 | Y7: 22 | Z7: 23 | AA7: 24 | AB7: 25 | AC7: Semana 4 | AD7: 27 | AE7: 28 | AF7: 29 | AG7: 31 | AH7: Semana 4
A8: 1 | B8: Fabricio Tapia Castedo | C8: Cochabamba | H8: =SUM(D8:G8) -> 0 | O8: =SUM(I8:N8) -> 0 | V8: =SUM(P8:U8) -> 0 | AC8: =SUM(W8:AB8) -> 0 | AH8: =SUM(AD8:AG8) -> 0 | AI8: =+H8+O8+V8+AH8 -> 0
A9: =1+A8 -> 2 | B9: Edwin Fernandez Chirinos | C9: El Alto | H9: =SUM(D9:G9) -> 0 | O9: =SUM(I9:N9) -> 0 | V9: =SUM(P9:U9) -> 0 | AC9: =SUM(W9:AB9) -> 0 | AH9: =SUM(AD9:AG9) -> 0 | AI9: =+H9+O9+V9+AH9 -> 0
A10: =1+A9 -> 3 | B10: Javier Caceres | C10: Cochabamba | H10: =SUM(D10:G10) -> 0 | O10: =SUM(I10:N10) -> 0 | V10: =SUM(P10:U10) -> 0 | AC10: =SUM(W10:AB10) -> 0 | AH10: =SUM(AD10:AG10) -> 0 | AI10: =+H10+O10+V10+AH10 -> 0
A11: =1+A10 -> 4 | B11: Juan Carlos Torrez Ayarde | C11: Tarija | H11: =SUM(D11:G11) -> 0 | O11: =SUM(I11:N11) -> 0 | V11: =SUM(P11:U11) -> 0 | AC11: =SUM(W11:AB11) -> 0 | AH11: =SUM(AD11:AG11) -> 0 | AI11: =+H11+O11+V11+AH11 -> 0
A12: =1+A11 -> 5 | B12: Carol Alejandra Noya | C12: Tarija | H12: =SUM(D12:G12) -> 0 | O12: =SUM(I12:N12) -> 0 | V12: =SUM(P12:U12) -> 0 | AC12: =SUM(W12:AB12) -> 0 | AH12: =SUM(AD12:AG12) -> 0 | AI12: =+H12+O12+V12+AH12 -> 0
A13: =1+A12 -> 6 | B13: Luis Alberto Chipana Peña | C13: Cochabamba | H13: =SUM(D13:G13) -> 0 | O13: =SUM(I13:N13) -> 0 | V13: =SUM(P13:U13) -> 0 | AC13: =SUM(W13:AB13) -> 0 | AH13: =SUM(AD13:AG13) -> 0 | AI13: =+H13+O13+V13+AH13 -> 0
A14: =1+A13 -> 7 | B14: Franz Carlos Alanez Flores | C14: El Alto | H14: =SUM(D14:G14) -> 0 | O14: =SUM(I14:N14) -> 0 | V14: =SUM(P14:U14) -> 0 | AC14: =SUM(W14:AB14) -> 0 | AH14: =SUM(AD14:AG14) -> 0 | AI14: =+H14+O14+V14+AH14 -> 0
A15: =1+A14 -> 8 | B15: Andrés Miguel Paniagua | C15: Oruro | H15: =SUM(D15:G15) -> 0 | O15: =SUM(I15:N15) -> 0 | V15: =SUM(P15:U15) -> 0 | AC15: =SUM(W15:AB15) -> 0 | AH15: =SUM(AD15:AG15) -> 0 | AI15: =+H15+O15+V15+AH15 -> 0
A16: =1+A15 -> 9 | B16: Alex Rolando Fernandez H. | C16: Oruro | H16: =SUM(D16:G16) -> 0 | O16: =SUM(I16:N16) -> 0 | V16: =SUM(P16:U16) -> 0 | AC16: =SUM(W16:AB16) -> 0 | AH16: =SUM(AD16:AG16) -> 0 | AI16: =+H16+O16+V16+AH16 -> 0
A17: =1+A16 -> 10 | B17: Franklin Ever Viveros | C17: Potosí | H17: =SUM(D17:G17) -> 0 | O17: =SUM(I17:N17) -> 0 | V17: =SUM(P17:U17) -> 0 | AC17: =SUM(W17:AB17) -> 0 | AH17: =SUM(AD17:AG17) -> 0 | AI17: =+H17+O17+V17+AH17 -> 0
A18: =1+A17 -> 11 | B18: Teofilo Ibañez Soliz | C18: Tarija | H18: =SUM(D18:G18) -> 0 | O18: =SUM(I18:N18) -> 0 | V18: =SUM(P18:U18) -> 0 | AC18: =SUM(W18:AB18) -> 0 | AH18: =SUM(AD18:AG18) -> 0 | AI18: =+H18+O18+V18+AH18 -> 0
A19: =1+A18 -> 12 | B19: Elsa Romay Padilla | C19: Uyuni | H19: =SUM(D19:G19) -> 0 | O19: =SUM(I19:N19) -> 0 | V19: =SUM(P19:U19) -> 0 | AC19: =SUM(W19:AB19) -> 0 | AH19: =SUM(AD19:AG19) -> 0 | AI19: =+H19+O19+V19+AH19 -> 0
A20: =1+A19 -> 13 | B20: Jorge Luis Vedia Arancibia | C20: Chuquisaca - Prov | H20: =SUM(D20:G20) -> 0 | O20: =SUM(I20:N20) -> 0 | V20: =SUM(P20:U20) -> 0 | AC20: =SUM(W20:AB20) -> 0 | AH20: =SUM(AD20:AG20) -> 0 | AI20: =+H20+O20+V20+AH20 -> 0
A21: =1+A20 -> 14 | B21: Celina Cruz Mendez | C21: Chuquisaca - Prov | H21: =SUM(D21:G21) -> 0 | O21: =SUM(I21:N21) -> 0 | V21: =SUM(P21:U21) -> 0 | AC21: =SUM(W21:AB21) -> 0 | AH21: =SUM(AD21:AG21) -> 0 | AI21: =+H21+O21+V21+AH21 -> 0
A22: =1+A28 -> 20 | B22: Marlene Paicho | C22: Ruta Colquechaca | H22: =SUM(D22:G22) -> 0 | O22: =SUM(I22:N22) -> 0 | V22: =SUM(P22:U22) -> 0 | AC22: =SUM(W22:AB22) -> 0 | AH22: =SUM(AD22:AG22) -> 0 | AI22: =H22+O22+V22+AH22 -> 0
A23: TOTAL CLIENTES MOROSOS | G23: =SUM(G8:G22) -> 0 | H23: =SUM(D23:G23) -> 0 | I23: =SUM(I8:I22) -> 0 | J23: =SUM(J8:J22) -> 0 | K23: =SUM(K8:K22) -> 0 | L23: =SUM(L8:L22) -> 0 | M23: =SUM(M8:M22) -> 0 | N23: =SUM(N8:N22) -> 0 | O23: =SUM(I23:N23) -> 0 | P23: =SUM(P8:P22) -> 0 | Q23: =SUM(Q8:Q22) -> 0 | R23: =SUM(R8:R22) -> 0 | S23: =SUM(S8:S22) -> 0 | T23: =SUM(T8:T22) -> 0 | U23: =SUM(U8:U22) -> 0 | V23: =SUM(P23:U23) -> 0 | W23: =SUM(W8:W22) -> 0 | X23: =SUM(X8:X22) -> 0 | Y23: =SUM(Y8:Y22) -> 0 | Z23: =SUM(Z8:Z22) -> 0 | AA23: =SUM(AA8:AA22) -> 0 | AB23: =SUM(AB8:AB22) -> 0 | AC23: =SUM(W23:AB23) -> 0 | AD23: =SUM(AD8:AD22) -> 0 | AG23: =SUM(AG8:AG22) -> 0 | AH23: =SUM(AD23:AG23) -> 0 | AI23: =SUM(AI8:AI22) -> 0
A24: =1+A21 -> 15 | B24: EMAPA NACIONAL | C24: NACIONAL | H24: =SUM(D24:G24) -> 0 | O24: =SUM(I24:N24) -> 0 | V24: =SUM(P24:U24) -> 0 | AC24: =SUM(W24:AB24) -> 0 | AH24: =SUM(AD24:AG24) -> 0 | AI24: =H24+O24+V24+AC24+AH24 -> 0
A25: =1+A24 -> 16 | B25: Gustavo Tellez Ugarte | C25: Santa Cruz | H25: =SUM(D25:G25) -> 0 | O25: =SUM(I25:N25) -> 0 | V25: =SUM(P25:U25) -> 0 | AC25: =SUM(W25:AB25) -> 0 | AG25: 84701 | AH25: =SUM(AD25:AG25) -> 84701 | AI25: =H25+O25+V25+AC25+AH25 -> 84701
A26: =1+A25 -> 17 | B26: Cristhian Murillo | C26: Sucre | H26: =SUM(D26:G26) -> 0 | O26: =SUM(I26:N26) -> 0 | V26: =SUM(P26:U26) -> 0 | AC26: =SUM(W26:AB26) -> 0 | AG26: 325114.12 | AH26: =SUM(AD26:AG26) -> 325114.12 | AI26: =H26+O26+V26+AC26+AH26 -> 325114.12
A27: =1+A26 -> 18 | B27: Sebastian Miranda | C27: Oruro | H27: =SUM(D27:G27) -> 0 | O27: =SUM(I27:N27) -> 0 | V27: =SUM(P27:U27) -> 0 | AC27: =SUM(W27:AB27) -> 0 | AH27: =SUM(AD27:AG27) -> 0 | AI27: =H27+O27+V27+AC27+AH27 -> 0
A28: =1+A27 -> 19 | B28: Norha Choque Talavera | C28: Potosí | H28: =SUM(D28:G28) -> 0 | O28: =SUM(I28:N28) -> 0 | V28: =SUM(P28:U28) -> 0 | AC28: =SUM(W28:AB28) -> 0 | AH28: =SUM(AD28:AG28) -> 0 | AI28: =H28+O28+V28+AC28+AH28 -> 0
A29: =1+A28 -> 20 | B29: Orlando Aldunate M. | C29: Tarija | H29: =SUM(D29:G29) -> 0 | O29: =SUM(I29:N29) -> 0 | V29: =SUM(P29:U29) -> 0 | AC29: =SUM(W29:AB29) -> 0 | AH29: =SUM(AD29:AG29) -> 0 | AI29: =H29+O29+V29+AC29+AH29 -> 0
A30: =1+A29 -> 21 | B30: Fausto Condori | C30: Cochabamba | H30: =SUM(D30:G30) -> 0 | O30: =SUM(I30:N30) -> 0 | V30: =SUM(P30:U30) -> 0 | AC30: =SUM(W30:AB30) -> 0 | AH30: =SUM(AD30:AG30) -> 0 | AI30: =H30+O30+V30+AC30+AH30 -> 0
A31: =1+A30 -> 22 | B31: Flora Yapuchura | C31: La Paz | H31: =SUM(D31:G31) -> 0 | O31: =SUM(I31:N31) -> 0 | V31: =SUM(P31:U31) -> 0 | AC31: =SUM(W31:AB31) -> 0 | AH31: =SUM(AD31:AG31) -> 0 | AI31: =H31+O31+V31+AC31+AH31 -> 0
A32: =1+A31 -> 23 | B32: Willy Quispe | C32: El Alto | H32: =SUM(D32:G32) -> 0 | O32: =SUM(I32:N32) -> 0 | V32: =SUM(P32:U32) -> 0 | AC32: =SUM(W32:AB32) -> 0 | AH32: =SUM(AD32:AG32) -> 0 | AI32: =H32+O32+V32+AC32+AH32 -> 0
A33: =1+A32 -> 24 | B33: Andrez Lopez | C33: Potosí | H33: =SUM(D33:G33) -> 0 | O33: =SUM(I33:N33) -> 0 | V33: =SUM(P33:U33) -> 0 | AC33: =SUM(W33:AB33) -> 0 | AH33: =SUM(AD33:AG33) -> 0 | AI33: =H33+O33+V33+AC33+AH33 -> 0
A34: =1+A33 -> 25 | B34: Miguel Angel Mora | C34: Potosí | H34: =SUM(D34:G34) -> 0 | O34: =SUM(I34:N34) -> 0 | V34: =SUM(P34:U34) -> 0 | AC34: =SUM(W34:AB34) -> 0 | AH34: =SUM(AD34:AG34) -> 0 | AI34: =H34+O34+V34+AC34+AH34 -> 0
